<?xml version='1.0' encoding='utf-8'?>
<robot name="h1_2">

  <mujoco>
    <compiler meshdir="meshes" discardvisual="false" />
  </mujoco>

  <!-- [CAUTION] uncomment when convert to mujoco -->
  <!-- <link name="world"></link>
  <joint name="floating_base_joint" type="floating">
    <parent link="world"/>
    <child link="pelvis"/>
  </joint> -->

  <link name="pelvis">
    <inertial>
      <origin xyz="-0.0004 3.7E-05 -0.046864" rpy="0 0 0" />
      <mass value="5.983" />
      <inertia ixx="49168.411E-06" ixy="-19.869E-06" ixz="-48.460E-06" iyy="9025.844E-06" iyz="3.431E-06" izz="53155.891E-06" />
    </inertial>
    </link>

  <!-- L Leg -->
  <link name="left_hip_yaw_link">
    <inertial>
      <origin xyz="0 -0.026197 0.006647" rpy="0 0 0" />
      <mass value="2.829" />
      <inertia ixx="4553.605E-06" ixy="0.005E-06" ixz="0.817E-06" iyy="5688.730E-06" iyz="-345.157E-06" izz="3548.907E-06" />
    </inertial>
    </link>
  <joint name="left_hip_yaw_joint" type="revolute">
    <origin xyz="0 0.0875 -0.1632" rpy="0 0 0" />
    <parent link="pelvis" />
    <child link="left_hip_yaw_link" />
    <axis xyz="0 0 1" />
    <limit lower="-0.43" upper="0.43" effort="200" velocity="23" />
  </joint>
  <link name="left_hip_pitch_link">
    <inertial>
      <origin xyz="-0.00781 -0.004724 -0.000063" rpy="0 0 0" />
      <mass value="2.920" />
      <inertia ixx="5594.7E-06" ixy="143.308E-06" ixz="-11.847E-06" iyy="3862.581E-06" iyz="-9.607E-06" izz="4450.563E-06" />
    </inertial>
    </link>
  <joint name="left_hip_pitch_joint" type="revolute">
    <origin xyz="0 0.0755 0" rpy="0 0 0" />
    <parent link="left_hip_yaw_link" />
    <child link="left_hip_pitch_link" />
    <axis xyz="0 1 0" />
    <limit lower="-3.14" upper="2.5" effort="200" velocity="23" />
  </joint>
  <link name="left_hip_roll_link">
    <inertial>
      <origin xyz="0.004171 -0.008576 -0.194509" rpy="0 0 0" />
      <mass value="4.962" />
      <inertia ixx="46305.869E-06" ixy="-322.626E-06" ixz="-1199.703E-06" iyy="47955.402E-06" iyz="288.147E-06" izz="8914.518E-06" />
    </inertial>
    </link>
  <joint name="left_hip_roll_joint" type="revolute">
    <origin xyz="0 0 0" rpy="0 0 0" />
    <parent link="left_hip_pitch_link" />
    <child link="left_hip_roll_link" />
    <axis xyz="1 0 0" />
    <limit lower="-0.43" upper="3.14" effort="200" velocity="23" />
  </joint>
  <link name="left_knee_link">
    <inertial>
      <origin xyz="0.000179 0.000121 -0.168936" rpy="0 0 0" />
      <mass value="3.839" />
      <inertia ixx="39002.363e-6" ixy="-72.364e-6" ixz="-794.506e-6" iyy="39042.376e-6" iyz="-18.663e-6" izz="5029.829e-6" />
    </inertial>
    </link>
  <joint name="left_knee_joint" type="revolute">
    <origin xyz="0 0 -0.4" rpy="0 0 0" />
    <parent link="left_hip_roll_link" />
    <child link="left_knee_link" />
    <axis xyz="0 1 0" />
    <limit lower="-0.12" upper="2.19" effort="300" velocity="14" />
  </joint>
  <link name="left_ankle_pitch_link">
    <inertial>
      <origin xyz="-0.000294 0 -0.010794" rpy="0 0 0" />
      <mass value="0.102" />
      <inertia ixx="0.000023944" ixy="0" ixz="0.000000121" iyy="0.000021837" iyz="0" izz="0.000013414" />
    </inertial>
    </link>
  <joint name="left_ankle_pitch_joint" type="revolute">
    <origin xyz="0 0 -0.4" rpy="0 0 0" />
    <parent link="left_knee_link" />
    <child link="left_ankle_pitch_link" />
    <axis xyz="0 1 0" />
    <limit lower="-0.897334" upper="0.523598" effort="60" velocity="9" />
  </joint>
  <link name="left_ankle_roll_link">
    <inertial>
      <origin xyz="0.029589 0 -0.015973" rpy="0 0 0" />
      <mass value="0.747" />
      <inertia ixx="648.830e-6" ixy="0" ixz="158.380e-6" iyy="3435.339e-6" iyz="0" izz="3583.259e-6" />
    </inertial>
    </link>
  <joint name="left_ankle_roll_joint" type="revolute">
    <origin xyz="0 0 -0.02" rpy="0 0 0" />
    <parent link="left_ankle_pitch_link" />
    <child link="left_ankle_roll_link" />
    <axis xyz="1 0 0" />
    <limit lower="-0.261799" upper="0.261799" effort="40" velocity="9" />
  </joint>

  <!-- R Leg -->
  <link name="right_hip_yaw_link">
    <inertial>
      <origin xyz="0 0.026197 0.006647" rpy="0 0 0" />
      <mass value="2.829" />
      <inertia ixx="4553.605E-06" ixy="-0.005E-06" ixz="0.817E-06" iyy="5688.730E-06" iyz="345.157E-06" izz="3548.907E-06" />
    </inertial>
    </link>
  <joint name="right_hip_yaw_joint" type="revolute">
    <origin xyz="0 -0.0875 -0.1632" rpy="0 0 0" />
    <parent link="pelvis" />
    <child link="right_hip_yaw_link" />
    <axis xyz="0 0 1" />
    <limit lower="-0.43" upper="0.43" effort="200" velocity="23" />
  </joint>
  <link name="right_hip_pitch_link">
    <inertial>
      <origin xyz="-0.00781 0.004724 -0.000063" rpy="0 0 0" />
      <mass value="2.920" />
      <inertia ixx="5594.7E-06" ixy="-143.308E-06" ixz="-11.847E-06" iyy="3862.581E-06" iyz="9.607E-06" izz="4450.563E-06" />
    </inertial>
    </link>
  <joint name="right_hip_pitch_joint" type="revolute">
    <origin xyz="0 -0.0755 0" rpy="0 0 0" />
    <parent link="right_hip_yaw_link" />
    <child link="right_hip_pitch_link" />
    <axis xyz="0 1 0" />
    <limit lower="-3.14" upper="2.5" effort="200" velocity="23" />
  </joint>
  <link name="right_hip_roll_link">
    <inertial>
      <origin xyz="0.004171 0.008576 -0.194509" rpy="0 0 0" />
      <mass value="4.962" />
      <inertia ixx="46305.869E-06" ixy="322.626E-06" ixz="-1199.703E-06" iyy="47955.402E-06" iyz="-288.147E-06" izz="8914.518E-06" />
    </inertial>
    </link>
  <joint name="right_hip_roll_joint" type="revolute">
    <origin xyz="0 0 0" rpy="0 0 0" />
    <parent link="right_hip_pitch_link" />
    <child link="right_hip_roll_link" />
    <axis xyz="1 0 0" />
    <limit lower="-3.14" upper="0.43" effort="200" velocity="23" />
  </joint>
  <link name="right_knee_link">
    <inertial>
      <origin xyz="0.000179 -0.000121 -0.168936" rpy="0 0 0" />
      <mass value="3.839" />
      <inertia ixx="39002.363e-6" ixy="72.364e-6" ixz="-794.506e-6" iyy="39042.376e-6" iyz="18.663e-6" izz="5029.829e-6" />
    </inertial>
    </link>
  <joint name="right_knee_joint" type="revolute">
    <origin xyz="0 0 -0.4" rpy="0 0 0" />
    <parent link="right_hip_roll_link" />
    <child link="right_knee_link" />
    <axis xyz="0 1 0" />
    <limit lower="-0.12" upper="2.19" effort="300" velocity="14" />
  </joint>
  <link name="right_ankle_pitch_link">
    <inertial>
      <origin xyz="-0.000294 0 -0.010794" rpy="0 0 0" />
      <mass value="0.102" />
      <inertia ixx="0.000023944" ixy="0" ixz="0.000000121" iyy="0.000021837" iyz="0" izz="0.000013414" />
    </inertial>
    </link>
  <joint name="right_ankle_pitch_joint" type="revolute">
    <origin xyz="0 0 -0.4" rpy="0 0 0" />
    <parent link="right_knee_link" />
    <child link="right_ankle_pitch_link" />
    <axis xyz="0 1 0" />
    <limit lower="-0.897334" upper="0.523598" effort="60" velocity="9" />
  </joint>
  <link name="right_ankle_roll_link">
    <inertial>
      <origin xyz="0.029589 0 -0.015973" rpy="0 0 0" />
      <mass value="0.747" />
      <inertia ixx="648.830e-6" ixy="0" ixz="158.380e-6" iyy="3435.339e-6" iyz="0" izz="3583.259e-6" />
    </inertial>
    </link>
  <joint name="right_ankle_roll_joint" type="revolute">
    <origin xyz="0 0 -0.02" rpy="0 0 0" />
    <parent link="right_ankle_pitch_link" />
    <child link="right_ankle_roll_link" />
    <axis xyz="1 0 0" />
    <limit lower="-0.261799" upper="0.261799" effort="40" velocity="9" />
  </joint>

  <!-- Torso -->
  <link name="torso_link">
    <inertial>
      <origin xyz="0.000489 0.002797 0.20484" rpy="0 0 0" />
      <mass value="17.789" />
      <inertia ixx="0.4873" ixy="-0.00053763" ixz="0.0020276" iyy="0.40963" iyz="-0.00074582" izz="0.12785" />
    </inertial>
    </link>
  <joint name="torso_joint" type="revolute">
    <origin xyz="0 0 0" rpy="0 0 0" />
    <parent link="pelvis" />
    <child link="torso_link" />
    <axis xyz="0 0 1" />
    <limit lower="-2.35" upper="2.35" effort="200" velocity="23" />
  </joint>

  <!-- L arm -->
  <link name="left_shoulder_pitch_link">
    <inertial>
      <origin xyz="0.003053 0.06042 -0.0059" rpy="0 0 0" />
      <mass value="1.327" />
      <inertia ixx="0.00058661" ixy="-2.0157E-05" ixz="2.985E-06" iyy="0.0003989" iyz="2.238E-05" izz="0.00052936" />
    </inertial>
    </link>
  <joint name="left_shoulder_pitch_joint" type="revolute">
    <origin xyz="0 0.14806 0.42333" rpy="0.2618 0 0" />
    <parent link="torso_link" />
    <child link="left_shoulder_pitch_link" />
    <axis xyz="0 1 0" />
    <limit lower="-3.14" upper="1.57" effort="40" velocity="9" />
  </joint>
  <link name="left_shoulder_roll_link">
    <inertial>
      <origin xyz="-0.030932 -1E-06 -0.10609" rpy="0 0 0" />
      <mass value="1.393" />
      <inertia ixx="0.0018408" ixy="3.98E-07" ixz="-0.00048324" iyy="0.001934638" iyz="1.61E-07" izz="0.000617733" />
    </inertial>
    </link>
  <joint name="left_shoulder_roll_joint" type="revolute">
    <origin xyz="0.0342 0.061999 -0.0060011" rpy="-0.2618 0 0" />
    <parent link="left_shoulder_pitch_link" />
    <child link="left_shoulder_roll_link" />
    <axis xyz="1 0 0" />
    <limit lower="-0.38" upper="3.4" effort="40" velocity="9" />
  </joint>
  <link name="left_shoulder_yaw_link">
    <inertial>
      <origin xyz="0.004583 0.001128 -0.001128" rpy="0 0 0" />
      <mass value="1.505" />
      <inertia ixx="0.004199" ixy="-1.7786E-05" ixz="0.00018372" iyy="0.0043139" iyz="9.278E-05" izz="0.00065755" />
    </inertial>
    </link>
  <joint name="left_shoulder_yaw_joint" type="revolute">
    <origin xyz="-0.0342 0 -0.1456" rpy="0 0 0" />
    <parent link="left_shoulder_roll_link" />
    <child link="left_shoulder_yaw_link" />
    <axis xyz="0 0 1" />
    <limit lower="-2.66" upper="3.01" effort="18" velocity="20" />
  </joint>
  <link name="left_elbow_link">
    <inertial>
      <origin xyz="0.077092 -0.028751 -0.009714 " rpy="0 0 0" />
      <mass value="0.691" />
      <inertia ixx="0.000318491" ixy="0.000224554" ixz="6.62076E-05" iyy="0.000861224" iyz="-2.3329E-05" izz="0.000897899" />
    </inertial>
    </link>
  <joint name="left_elbow_joint" type="revolute">
    <origin xyz="0.006 0.0329 -0.182" rpy="0 0 0" />
    <parent link="left_shoulder_yaw_link" />
    <child link="left_elbow_link" />
    <axis xyz="0 1 0" />
    <limit lower="-0.95" upper="3.18" effort="18" velocity="20" />
  </joint>

  <link name="left_wrist_roll_link">
    <inertial>
      <origin xyz="0.035281 -0.002320 0.000337" rpy="0 0 0" />
      <mass value="0.683" />
      <inertia ixx="0.000313275" ixy="0.000016521" ixz="-0.000002501" iyy="0.000310412" iyz="0.000005435" izz="0.000345998" />
    </inertial>
    </link>
  <joint name="left_wrist_roll_joint" type="revolute">
    <origin xyz="0.121 -0.0329 -0.011" rpy="0 0 0" />
    <parent link="left_elbow_link" />
    <child link="left_wrist_roll_link" />
    <axis xyz="1 0 0" />
    <limit lower="-3.01" upper="2.75" effort="19" velocity="31.4" />
  </joint>

  <link name="left_wrist_pitch_link">
    <inertial>
      <origin xyz="0.020395 0.000036 -0.002973" rpy="0 0 0" />
      <mass value="0.484" />
      <inertia ixx="0.000071364" ixy="0.000000308" ixz="0.000001485" iyy="0.000069915" iyz="-0.000000088" izz="0.000070702" />
    </inertial>
    </link>
  <joint name="left_wrist_pitch_joint" type="revolute">
    <origin xyz="0.087 0 0" rpy="0 0 0" />
    <parent link="left_wrist_roll_link" />
    <child link="left_wrist_pitch_link" />
    <axis xyz="0 1 0" />
    <limit lower="-0.4625" upper="0.4625" effort="19" velocity="31.4" />
  </joint>
  <link name="left_wrist_yaw_link">
    <inertial>
      <origin xyz="0.027967 0.000096 0.000739" rpy="0 0 0" />
      <mass value="0.124" />
      <inertia ixx="137.3e-6" ixy="-0.171e-6" ixz="2.942e-6" iyy="169.998e-6" iyz="-0.025e-6" izz="84.808e-6" />
    </inertial>
    <!-- <collision>
      <origin xyz="0 0 0" rpy="0 0 0"/>
      <geometry>
        <mesh filename="meshes/wrist_yaw_link.STL"/>
      </geometry>
    </collision> -->
  </link>
  <joint name="left_wrist_yaw_joint" type="revolute">
    <origin xyz="0.020 0 0" rpy="0 0 0" />
    <parent link="left_wrist_pitch_link" />
    <child link="left_wrist_yaw_link" />
    <axis xyz="0 0 1" />
    <limit lower="-1.27" upper="1.27" effort="19" velocity="31.4" />
  </joint>

  <!-- R arm -->
  <link name="right_shoulder_pitch_link">
    <inertial>
      <origin xyz="0.003053 -0.06042 -0.0059" rpy="0 0 0" />
      <mass value="1.327" />
      <inertia ixx="0.00058661" ixy="2.0157E-05" ixz="2.985E-06" iyy="0.0003989" iyz="-2.238E-05" izz="0.00052936" />
    </inertial>
    </link>
  <joint name="right_shoulder_pitch_joint" type="revolute">
    <origin xyz="0 -0.14806 0.42333" rpy="-0.2618 0 0" />
    <parent link="torso_link" />
    <child link="right_shoulder_pitch_link" />
    <axis xyz="0 1 0" />
    <limit lower="-3.14" upper="1.57" effort="40" velocity="9" />
  </joint>
  <link name="right_shoulder_roll_link">
    <inertial>
      <origin xyz="-0.030932 1E-06 -0.10609" rpy="0 0 0" />
      <mass value="1.393" />
      <inertia ixx="0.0018408" ixy="-3.98E-07" ixz="-0.00048324" iyy="0.001934638" iyz="-1.61E-07" izz="0.000617733" />
    </inertial>
    </link>
  <joint name="right_shoulder_roll_joint" type="revolute">
    <origin xyz="0.0342 -0.061999 -0.0060011" rpy="0.2618 0 0" />
    <parent link="right_shoulder_pitch_link" />
    <child link="right_shoulder_roll_link" />
    <axis xyz="1 0 0" />
    <limit lower="-3.4" upper="0.38" effort="40" velocity="9" />
  </joint>
  <link name="right_shoulder_yaw_link">
    <inertial>
      <origin xyz="0.004583 -0.001128 -0.001128" rpy="0 0 0" />
      <mass value="1.505" />
      <inertia ixx="0.004199" ixy="1.7786E-05" ixz="0.00018372" iyy="0.0043139" iyz="-9.278E-05" izz="0.00065755" />

    </inertial>
    </link>
  <joint name="right_shoulder_yaw_joint" type="revolute">
    <origin xyz="-0.0342 0 -0.1456" rpy="0 0 0" />
    <parent link="right_shoulder_roll_link" />
    <child link="right_shoulder_yaw_link" />
    <axis xyz="0 0 1" />
    <limit lower="-3.01" upper="2.66" effort="18" velocity="20" />
  </joint>
  <link name="right_elbow_link">
    <inertial>
      <origin xyz="0.077092 0.028751 -0.009714 " rpy="0 0 0" />
      <mass value="0.691" />
      <inertia ixx="0.000318491" ixy="-0.000224554" ixz="6.62076E-05" iyy="0.000861224" iyz="2.3329E-05" izz="0.000897899" />
    </inertial>
    </link>
  <joint name="right_elbow_joint" type="revolute">
    <origin xyz="0.006 -0.0329 -0.182" rpy="0 0 0" />
    <parent link="right_shoulder_yaw_link" />
    <child link="right_elbow_link" />
    <axis xyz="0 1 0" />
    <limit lower="-0.95" upper="3.18" effort="18" velocity="20" />
  </joint>

  <link name="right_wrist_roll_link">
    <inertial>
      <origin xyz="0.035281 -0.002320 0.000337" rpy="0 0 0" />
      <mass value="0.683" />
      <inertia ixx="0.000313275" ixy="0.000016521" ixz="-0.000002501" iyy="0.000310412" iyz="0.000005435" izz="0.000345998" />
    </inertial>
    </link>
  <joint name="right_wrist_roll_joint" type="revolute">
    <origin xyz="0.121 0.0329 -0.011" rpy="0 0 0" />
    <parent link="right_elbow_link" />
    <child link="right_wrist_roll_link" />
    <axis xyz="1 0 0" />
    <limit lower="-2.75" upper="3.01" effort="19" velocity="31.4" />
  </joint>

  <link name="right_wrist_pitch_link">
    <inertial>
      <origin xyz="0.020395 0.000036 -0.002973" rpy="0 0 0" />
      <mass value="0.484" />
      <inertia ixx="0.000071364" ixy="0.000000308" ixz="0.000001485" iyy="0.000069915" iyz="-0.000000088" izz="0.000070702" />
    </inertial>
    </link>
  <joint name="right_wrist_pitch_joint" type="revolute">
    <origin xyz="0.087 0 0" rpy="0 0 0" />
    <parent link="right_wrist_roll_link" />
    <child link="right_wrist_pitch_link" />
    <axis xyz="0 1 0" />
    <limit lower="-0.4625" upper="0.4625" effort="19" velocity="31.4" />
  </joint>
  <link name="right_wrist_yaw_link">
    <inertial>
      <origin xyz="0.027967 -0.000096 0.000739" rpy="0 0 0" />
      <mass value="0.124" />
      <inertia ixx="137.3e-6" ixy="0.171e-6" ixz="2.942e-6" iyy="169.998e-6" iyz="0.025e-6" izz="84.808e-6" />
    </inertial>
    <!-- <collision>
      <origin xyz="0 0 0" rpy="0 0 0"/>
      <geometry>
        <mesh filename="meshes/wrist_yaw_link.STL"/>
      </geometry>
    </collision> -->
  </link>
  <joint name="right_wrist_yaw_joint" type="revolute">
    <origin xyz="0.020 0 0" rpy="0 0 0" />
    <parent link="right_wrist_pitch_link" />
    <child link="right_wrist_yaw_link" />
    <axis xyz="0 0 1" />
    <limit lower="-1.27" upper="1.27" effort="19" velocity="31.4" />
  </joint>

  <!-- LOGO -->
  <link name="logo_link">
    </link>
  <joint name="logo_joint" type="fixed">
    <origin xyz="0 0 0" rpy="0 0 0" />
    <parent link="torso_link" />
    <child link="logo_link" />
    <axis xyz="0 0 0" />
  </joint>

  <!-- IMU -->
  <link name="imu_link" />
  <joint name="imu_joint" type="fixed">
    <origin xyz="-0.04452 -0.01891 0.27756" rpy="0 0 0" />
    <parent link="torso_link" />
    <child link="imu_link" />
  </joint>

  <!-- Camera&Lidar -->
  <!--
  <link name="camera_link"></link>
  <joint name="camera_joint" type="fixed">
    <origin xyz="0.11109 0.01750 0.68789" rpy="0 0.8859291283123216 0"/>
    <parent link="torso_link"/>
    <child link="camera_link"/>
  </joint>
  <link name="lidar_link"></link>
  <joint name="lidar_joint" type="fixed">
    <origin xyz="0.04874 0 0.67980" rpy="0 0.24015730507441985 0"/>
    <parent link="torso_link"/>
    <child link="lidar_link"/>
  </joint>
  -->

  <!-- LiDAR -->
  <link name="lidar_link" />
  <joint name="lidar_joint" type="fixed">
    <origin xyz="0.04874 0 0.679808" rpy="0 -2.90143535 0" />
    <parent link="torso_link" />
    <child link="lidar_link" />
  </joint>

  <!-- Head Camera -->
  <link name="head_camera_link" />
  <joint name="head_camera_joint" type="fixed">
    <origin xyz="0.11109 0.01750 0.68789" rpy="-2.45672546 0 -1.5708" />
    <parent link="torso_link" />
    <child link="head_camera_link" />
  </joint>

  <!-- Left Wrist Camera -->
  <link name="left_hand_camera_link" />
  <joint name="left_hand_camera_joint" type="fixed">
    <origin xyz="0 0.04 0" rpy="0 1.5708 0" />
    <parent link="left_wrist_yaw_link" />
    <child link="left_hand_camera_link" />
  </joint>

  <!-- Right Wrist Camera -->
  <link name="right_hand_camera_link" />
  <joint name="right_hand_camera_joint" type="fixed">
    <origin xyz="0 -0.04 0" rpy="-3.1415 -1.5708 0" />
    <parent link="right_wrist_yaw_link" />
    <child link="right_hand_camera_link" />
  </joint>
<link name="pelvis_sphere1"><inertial><origin xyz="0 0 0" rpy="0 0 0" /><mass value="0.01" /><inertia ixx="0.001" ixy="0" ixz="0" iyy="0.001" iyz="0" izz="0.001" /></inertial><visual><origin rpy="0 0 0" xyz="0 0 0" /><geometry><sphere radius="0.06357467174530029" /></geometry><material name="color_pelvis_sphere1_0"><color rgba="0.9 0.2 0.2 1.0" /></material></visual><collision><origin rpy="0 0 0" xyz="0 0 0" /><geometry><sphere radius="0.06357467174530029" /></geometry><drake:proximity_properties><drake:rigid_hydroelastic /><drake:mesh_resolution_hint value="1.5" /><drake:hunt_crossley_dissipation value="1.25" /></drake:proximity_properties></collision></link><joint name="pelvis_to_pelvis_sphere1" type="fixed"><parent link="pelvis" /><child link="pelvis_sphere1" /><origin xyz="0.0003403265727683902 0.0009708564612083137 -0.038669947534799576" rpy="0 0 0" /></joint><link name="pelvis_sphere2"><inertial><origin xyz="0 0 0" rpy="0 0 0" /><mass value="0.01" /><inertia ixx="0.001" ixy="0" ixz="0" iyy="0.001" iyz="0" izz="0.001" /></inertial><visual><origin rpy="0 0 0" xyz="0 0 0" /><geometry><sphere radius="0.05728628858923912" /></geometry><material name="color_pelvis_sphere2_0"><color rgba="0.9 0.2 0.2 1.0" /></material></visual><collision><origin rpy="0 0 0" xyz="0 0 0" /><geometry><sphere radius="0.05728628858923912" /></geometry><drake:proximity_properties><drake:rigid_hydroelastic /><drake:mesh_resolution_hint value="1.5" /><drake:hunt_crossley_dissipation value="1.25" /></drake:proximity_properties></collision></link><joint name="pelvis_to_pelvis_sphere2" type="fixed"><parent link="pelvis" /><child link="pelvis_sphere2" /><origin xyz="-0.0011067589512094855 -0.09178908914327621 -0.04199345409870148" rpy="0 0 0" /></joint><link name="pelvis_sphere3"><inertial><origin xyz="0 0 0" rpy="0 0 0" /><mass value="0.01" /><inertia ixx="0.001" ixy="0" ixz="0" iyy="0.001" iyz="0" izz="0.001" /></inertial><visual><origin rpy="0 0 0" xyz="0 0 0" /><geometry><sphere radius="0.05668027326464653" /></geometry><material name="color_pelvis_sphere3_0"><color rgba="0.9 0.2 0.2 1.0" /></material></visual><collision><origin rpy="0 0 0" xyz="0 0 0" /><geometry><sphere radius="0.05668027326464653" /></geometry><drake:proximity_properties><drake:rigid_hydroelastic /><drake:mesh_resolution_hint value="1.5" /><drake:hunt_crossley_dissipation value="1.25" /></drake:proximity_properties></collision></link><joint name="pelvis_to_pelvis_sphere3" type="fixed"><parent link="pelvis" /><child link="pelvis_sphere3" /><origin xyz="-0.0006564579671248794 0.09162865579128265 -0.04301179572939873" rpy="0 0 0" /></joint><link name="torso_link_sphere1"><inertial><origin xyz="0 0 0" rpy="0 0 0" /><mass value="0.01" /><inertia ixx="0.001" ixy="0" ixz="0" iyy="0.001" iyz="0" izz="0.001" /></inertial><visual><origin rpy="0 0 0" xyz="0 0 0" /><geometry><sphere radius="0.10618707537651062" /></geometry><material name="color_torso_link_sphere1_0"><color rgba="0.9 0.2 0.2 1.0" /></material></visual><collision><origin rpy="0 0 0" xyz="0 0 0" /><geometry><sphere radius="0.10618707537651062" /></geometry><drake:proximity_properties><drake:rigid_hydroelastic /><drake:mesh_resolution_hint value="1.5" /><drake:hunt_crossley_dissipation value="1.25" /></drake:proximity_properties></collision></link><joint name="torso_link_to_torso_link_sphere1" type="fixed"><parent link="torso_link" /><child link="torso_link_sphere1" /><origin xyz="0.003478483995422721 -0.0007865214138291776 0.09114999324083328" rpy="0 0 0" /></joint><link name="torso_link_sphere2"><inertial><origin xyz="0 0 0" rpy="0 0 0" /><mass value="0.01" /><inertia ixx="0.001" ixy="0" ixz="0" iyy="0.001" iyz="0" izz="0.001" /></inertial><visual><origin rpy="0 0 0" xyz="0 0 0" /><geometry><sphere radius="0.08893471956253052" /></geometry><material name="color_torso_link_sphere2_0"><color rgba="0.9 0.2 0.2 1.0" /></material></visual><collision><origin rpy="0 0 0" xyz="0 0 0" /><geometry><sphere radius="0.08893471956253052" /></geometry><drake:proximity_properties><drake:rigid_hydroelastic /><drake:mesh_resolution_hint value="1.5" /><drake:hunt_crossley_dissipation value="1.25" /></drake:proximity_properties></collision></link><joint name="torso_link_to_torso_link_sphere2" type="fixed"><parent link="torso_link" /><child link="torso_link_sphere2" /><origin xyz="0.04515593871474266 -4.1305967897642404e-05 0.6715702414512634" rpy="0 0 0" /></joint><link name="torso_link_sphere3"><inertial><origin xyz="0 0 0" rpy="0 0 0" /><mass value="0.01" /><inertia ixx="0.001" ixy="0" ixz="0" iyy="0.001" iyz="0" izz="0.001" /></inertial><visual><origin rpy="0 0 0" xyz="0 0 0" /><geometry><sphere radius="0.11969899386167526" /></geometry><material name="color_torso_link_sphere3_0"><color rgba="0.9 0.2 0.2 1.0" /></material></visual><collision><origin rpy="0 0 0" xyz="0 0 0" /><geometry><sphere radius="0.11969899386167526" /></geometry><drake:proximity_properties><drake:rigid_hydroelastic /><drake:mesh_resolution_hint value="1.5" /><drake:hunt_crossley_dissipation value="1.25" /></drake:proximity_properties></collision></link><joint name="torso_link_to_torso_link_sphere3" type="fixed"><parent link="torso_link" /><child link="torso_link_sphere3" /><origin xyz="0.0101136090233922 -0.00015289020666386932 0.30636510252952576" rpy="0 0 0" /></joint><link name="torso_link_sphere4"><inertial><origin xyz="0 0 0" rpy="0 0 0" /><mass value="0.01" /><inertia ixx="0.001" ixy="0" ixz="0" iyy="0.001" iyz="0" izz="0.001" /></inertial><visual><origin rpy="0 0 0" xyz="0 0 0" /><geometry><sphere radius="0.11274947226047516" /></geometry><material name="color_torso_link_sphere4_0"><color rgba="0.9 0.2 0.2 1.0" /></material></visual><collision><origin rpy="0 0 0" xyz="0 0 0" /><geometry><sphere radius="0.11274947226047516" /></geometry><drake:proximity_properties><drake:rigid_hydroelastic /><drake:mesh_resolution_hint value="1.5" /><drake:hunt_crossley_dissipation value="1.25" /></drake:proximity_properties></collision></link><joint name="torso_link_to_torso_link_sphere4" type="fixed"><parent link="torso_link" /><child link="torso_link_sphere4" /><origin xyz="0.020222892984747887 0.00037389458157122135 0.5121726393699646" rpy="0 0 0" /></joint><link name="left_shoulder_pitch_link_sphere1"><inertial><origin xyz="0 0 0" rpy="0 0 0" /><mass value="0.01" /><inertia ixx="0.001" ixy="0" ixz="0" iyy="0.001" iyz="0" izz="0.001" /></inertial><visual><origin rpy="0 0 0" xyz="0 0 0" /><geometry><sphere radius="0.05021890252828598" /></geometry><material name="color_left_shoulder_pitch_link_sphere1_0"><color rgba="1.0 1.0 0.2 1.0" /></material></visual><collision><origin rpy="0 0 0" xyz="0 0 0" /><geometry><sphere radius="0.05021890252828598" /></geometry><drake:proximity_properties><drake:rigid_hydroelastic /><drake:mesh_resolution_hint value="1.5" /><drake:hunt_crossley_dissipation value="1.25" /></drake:proximity_properties></collision></link><joint name="left_shoulder_pitch_link_to_left_shoulder_pitch_link_sphere1" type="fixed"><parent link="left_shoulder_pitch_link" /><child link="left_shoulder_pitch_link_sphere1" /><origin xyz="-0.003680610563606024 0.05464700236916542 -0.005241498351097107" rpy="0 0 0" /></joint><link name="left_shoulder_roll_link_sphere1"><inertial><origin xyz="0 0 0" rpy="0 0 0" /><mass value="0.01" /><inertia ixx="0.001" ixy="0" ixz="0" iyy="0.001" iyz="0" izz="0.001" /></inertial><visual><origin rpy="0 0 0" xyz="0 0 0" /><geometry><sphere radius="0.0561298243701458" /></geometry><material name="color_left_shoulder_roll_link_sphere1_0"><color rgba="1.0 0.84 0.0 1.0" /></material></visual><collision><origin rpy="0 0 0" xyz="0 0 0" /><geometry><sphere radius="0.0561298243701458" /></geometry><drake:proximity_properties><drake:rigid_hydroelastic /><drake:mesh_resolution_hint value="1.5" /><drake:hunt_crossley_dissipation value="1.25" /></drake:proximity_properties></collision></link><joint name="left_shoulder_roll_link_to_left_shoulder_roll_link_sphere1" type="fixed"><parent link="left_shoulder_roll_link" /><child link="left_shoulder_roll_link_sphere1" /><origin xyz="-0.02705514244735241 -0.0003540052566677332 -0.07903210818767548" rpy="0 0 0" /></joint><link name="left_shoulder_yaw_link_sphere1"><inertial><origin xyz="0 0 0" rpy="0 0 0" /><mass value="0.01" /><inertia ixx="0.001" ixy="0" ixz="0" iyy="0.001" iyz="0" izz="0.001" /></inertial><visual><origin rpy="0 0 0" xyz="0 0 0" /><geometry><sphere radius="0.04590257629752159" /></geometry><material name="color_left_shoulder_yaw_link_sphere1_0"><color rgba="0.8 0.52 0.25 1.0" /></material></visual><collision><origin rpy="0 0 0" xyz="0 0 0" /><geometry><sphere radius="0.04590257629752159" /></geometry><drake:proximity_properties><drake:rigid_hydroelastic /><drake:mesh_resolution_hint value="1.5" /><drake:hunt_crossley_dissipation value="1.25" /></drake:proximity_properties></collision></link><joint name="left_shoulder_yaw_link_to_left_shoulder_yaw_link_sphere1" type="fixed"><parent link="left_shoulder_yaw_link" /><child link="left_shoulder_yaw_link_sphere1" /><origin xyz="0.0011504257563501596 -0.0008248673984780908 -0.0346042662858963" rpy="0 0 0" /></joint><link name="left_shoulder_yaw_link_sphere2"><inertial><origin xyz="0 0 0" rpy="0 0 0" /><mass value="0.01" /><inertia ixx="0.001" ixy="0" ixz="0" iyy="0.001" iyz="0" izz="0.001" /></inertial><visual><origin rpy="0 0 0" xyz="0 0 0" /><geometry><sphere radius="0.04926080256700516" /></geometry><material name="color_left_shoulder_yaw_link_sphere2_0"><color rgba="0.8 0.52 0.25 1.0" /></material></visual><collision><origin rpy="0 0 0" xyz="0 0 0" /><geometry><sphere radius="0.04926080256700516" /></geometry><drake:proximity_properties><drake:rigid_hydroelastic /><drake:mesh_resolution_hint value="1.5" /><drake:hunt_crossley_dissipation value="1.25" /></drake:proximity_properties></collision></link><joint name="left_shoulder_yaw_link_to_left_shoulder_yaw_link_sphere2" type="fixed"><parent link="left_shoulder_yaw_link" /><child link="left_shoulder_yaw_link_sphere2" /><origin xyz="0.006146916653960943 -0.0043021757155656815 -0.18221591413021088" rpy="0 0 0" /></joint><link name="left_shoulder_yaw_link_sphere3"><inertial><origin xyz="0 0 0" rpy="0 0 0" /><mass value="0.01" /><inertia ixx="0.001" ixy="0" ixz="0" iyy="0.001" iyz="0" izz="0.001" /></inertial><visual><origin rpy="0 0 0" xyz="0 0 0" /><geometry><sphere radius="0.048234403133392334" /></geometry><material name="color_left_shoulder_yaw_link_sphere3_0"><color rgba="0.8 0.52 0.25 1.0" /></material></visual><collision><origin rpy="0 0 0" xyz="0 0 0" /><geometry><sphere radius="0.048234403133392334" /></geometry><drake:proximity_properties><drake:rigid_hydroelastic /><drake:mesh_resolution_hint value="1.5" /><drake:hunt_crossley_dissipation value="1.25" /></drake:proximity_properties></collision></link><joint name="left_shoulder_yaw_link_to_left_shoulder_yaw_link_sphere3" type="fixed"><parent link="left_shoulder_yaw_link" /><child link="left_shoulder_yaw_link_sphere3" /><origin xyz="0.003462175140157342 -0.0024497846607118845 -0.10537935793399811" rpy="0 0 0" /></joint><link name="left_elbow_link_sphere1"><inertial><origin xyz="0 0 0" rpy="0 0 0" /><mass value="0.01" /><inertia ixx="0.001" ixy="0" ixz="0" iyy="0.001" iyz="0" izz="0.001" /></inertial><visual><origin rpy="0 0 0" xyz="0 0 0" /><geometry><sphere radius="0.037453651428222656" /></geometry><material name="color_left_elbow_link_sphere1_0"><color rgba="0.95 0.95 0.5 1.0" /></material></visual><collision><origin rpy="0 0 0" xyz="0 0 0" /><geometry><sphere radius="0.037453651428222656" /></geometry><drake:proximity_properties><drake:rigid_hydroelastic /><drake:mesh_resolution_hint value="1.5" /><drake:hunt_crossley_dissipation value="1.25" /></drake:proximity_properties></collision></link><joint name="left_elbow_link_to_left_elbow_link_sphere1" type="fixed"><parent link="left_elbow_link" /><child link="left_elbow_link_sphere1" /><origin xyz="0.008503979071974754 -0.01428496278822422 -0.0016332389786839485" rpy="0 0 0" /></joint><link name="left_elbow_link_sphere2"><inertial><origin xyz="0 0 0" rpy="0 0 0" /><mass value="0.01" /><inertia ixx="0.001" ixy="0" ixz="0" iyy="0.001" iyz="0" izz="0.001" /></inertial><visual><origin rpy="0 0 0" xyz="0 0 0" /><geometry><sphere radius="0.04101834446191788" /></geometry><material name="color_left_elbow_link_sphere2_0"><color rgba="0.95 0.95 0.5 1.0" /></material></visual><collision><origin rpy="0 0 0" xyz="0 0 0" /><geometry><sphere radius="0.04101834446191788" /></geometry><drake:proximity_properties><drake:rigid_hydroelastic /><drake:mesh_resolution_hint value="1.5" /><drake:hunt_crossley_dissipation value="1.25" /></drake:proximity_properties></collision></link><joint name="left_elbow_link_to_left_elbow_link_sphere2" type="fixed"><parent link="left_elbow_link" /><child link="left_elbow_link_sphere2" /><origin xyz="0.08459305018186569 -0.0312232356518507 -0.008993495255708694" rpy="0 0 0" /></joint><link name="left_wrist_roll_link_sphere1"><inertial><origin xyz="0 0 0" rpy="0 0 0" /><mass value="0.01" /><inertia ixx="0.001" ixy="0" ixz="0" iyy="0.001" iyz="0" izz="0.001" /></inertial><visual><origin rpy="0 0 0" xyz="0 0 0" /><geometry><sphere radius="0.04320788383483887" /></geometry><material name="color_left_wrist_roll_link_sphere1_0"><color rgba="0.7 0.5 0.1 1.0" /></material></visual><collision><origin rpy="0 0 0" xyz="0 0 0" /><geometry><sphere radius="0.04320788383483887" /></geometry><drake:proximity_properties><drake:rigid_hydroelastic /><drake:mesh_resolution_hint value="1.5" /><drake:hunt_crossley_dissipation value="1.25" /></drake:proximity_properties></collision></link><joint name="left_wrist_roll_link_to_left_wrist_roll_link_sphere1" type="fixed"><parent link="left_wrist_roll_link" /><child link="left_wrist_roll_link_sphere1" /><origin xyz="0.04196289926767349 -0.0007462173816747963 -0.00012633352889679372" rpy="0 0 0" /></joint><link name="left_wrist_pitch_link_sphere1"><inertial><origin xyz="0 0 0" rpy="0 0 0" /><mass value="0.01" /><inertia ixx="0.001" ixy="0" ixz="0" iyy="0.001" iyz="0" izz="0.001" /></inertial><visual><origin rpy="0 0 0" xyz="0 0 0" /><geometry><sphere radius="0.03572520613670349" /></geometry><material name="color_left_wrist_pitch_link_sphere1_0"><color rgba="1.0 0.9 0.4 1.0" /></material></visual><collision><origin rpy="0 0 0" xyz="0 0 0" /><geometry><sphere radius="0.03572520613670349" /></geometry><drake:proximity_properties><drake:rigid_hydroelastic /><drake:mesh_resolution_hint value="1.5" /><drake:hunt_crossley_dissipation value="1.25" /></drake:proximity_properties></collision></link><joint name="left_wrist_pitch_link_to_left_wrist_pitch_link_sphere1" type="fixed"><parent link="left_wrist_pitch_link" /><child link="left_wrist_pitch_link_sphere1" /><origin xyz="0.019083457067608833 -4.399214594741352e-05 0.0007478207116946578" rpy="0 0 0" /></joint><link name="left_wrist_yaw_link_sphere1"><inertial><origin xyz="0 0 0" rpy="0 0 0" /><mass value="0.01" /><inertia ixx="0.001" ixy="0" ixz="0" iyy="0.001" iyz="0" izz="0.001" /></inertial><visual><origin rpy="0 0 0" xyz="0 0 0" /><geometry><sphere radius="0.0401243194937706" /></geometry><material name="color_left_wrist_yaw_link_sphere1_0"><color rgba="0.6 0.4 0.1 1.0" /></material></visual><collision><origin rpy="0 0 0" xyz="0 0 0" /><geometry><sphere radius="0.0401243194937706" /></geometry><drake:proximity_properties><drake:rigid_hydroelastic /><drake:mesh_resolution_hint value="1.5" /><drake:hunt_crossley_dissipation value="1.25" /></drake:proximity_properties></collision></link><joint name="left_wrist_yaw_link_to_left_wrist_yaw_link_sphere1" type="fixed"><parent link="left_wrist_yaw_link" /><child link="left_wrist_yaw_link_sphere1" /><origin xyz="0.025164952501654625 -0.0002986877807416022 -8.146732579916716e-05" rpy="0 0 0" /></joint><link name="right_shoulder_pitch_link_sphere1"><inertial><origin xyz="0 0 0" rpy="0 0 0" /><mass value="0.01" /><inertia ixx="0.001" ixy="0" ixz="0" iyy="0.001" iyz="0" izz="0.001" /></inertial><visual><origin rpy="0 0 0" xyz="0 0 0" /><geometry><sphere radius="0.05052950978279114" /></geometry><material name="color_right_shoulder_pitch_link_sphere1_0"><color rgba="0.8 0.2 1.0 1.0" /></material></visual><collision><origin rpy="0 0 0" xyz="0 0 0" /><geometry><sphere radius="0.05052950978279114" /></geometry><drake:proximity_properties><drake:rigid_hydroelastic /><drake:mesh_resolution_hint value="1.5" /><drake:hunt_crossley_dissipation value="1.25" /></drake:proximity_properties></collision></link><joint name="right_shoulder_pitch_link_to_right_shoulder_pitch_link_sphere1" type="fixed"><parent link="right_shoulder_pitch_link" /><child link="right_shoulder_pitch_link_sphere1" /><origin xyz="-0.00400080531835556 -0.054801035672426224 -0.005326153244823217" rpy="0 0 0" /></joint><link name="right_shoulder_roll_link_sphere1"><inertial><origin xyz="0 0 0" rpy="0 0 0" /><mass value="0.01" /><inertia ixx="0.001" ixy="0" ixz="0" iyy="0.001" iyz="0" izz="0.001" /></inertial><visual><origin rpy="0 0 0" xyz="0 0 0" /><geometry><sphere radius="0.05629420652985573" /></geometry><material name="color_right_shoulder_roll_link_sphere1_0"><color rgba="0.6 0.3 0.8 1.0" /></material></visual><collision><origin rpy="0 0 0" xyz="0 0 0" /><geometry><sphere radius="0.05629420652985573" /></geometry><drake:proximity_properties><drake:rigid_hydroelastic /><drake:mesh_resolution_hint value="1.5" /><drake:hunt_crossley_dissipation value="1.25" /></drake:proximity_properties></collision></link><joint name="right_shoulder_roll_link_to_right_shoulder_roll_link_sphere1" type="fixed"><parent link="right_shoulder_roll_link" /><child link="right_shoulder_roll_link_sphere1" /><origin xyz="-0.027096537873148918 -0.0006400610436685383 -0.07835514843463898" rpy="0 0 0" /></joint><link name="right_shoulder_yaw_link_sphere1"><inertial><origin xyz="0 0 0" rpy="0 0 0" /><mass value="0.01" /><inertia ixx="0.001" ixy="0" ixz="0" iyy="0.001" iyz="0" izz="0.001" /></inertial><visual><origin rpy="0 0 0" xyz="0 0 0" /><geometry><sphere radius="0.04954177513718605" /></geometry><material name="color_right_shoulder_yaw_link_sphere1_0"><color rgba="0.5 0.1 0.5 1.0" /></material></visual><collision><origin rpy="0 0 0" xyz="0 0 0" /><geometry><sphere radius="0.04954177513718605" /></geometry><drake:proximity_properties><drake:rigid_hydroelastic /><drake:mesh_resolution_hint value="1.5" /><drake:hunt_crossley_dissipation value="1.25" /></drake:proximity_properties></collision></link><joint name="right_shoulder_yaw_link_to_right_shoulder_yaw_link_sphere1" type="fixed"><parent link="right_shoulder_yaw_link" /><child link="right_shoulder_yaw_link_sphere1" /><origin xyz="0.006087132729589939 0.004507239907979965 -0.18166829645633698" rpy="0 0 0" /></joint><link name="right_shoulder_yaw_link_sphere2"><inertial><origin xyz="0 0 0" rpy="0 0 0" /><mass value="0.01" /><inertia ixx="0.001" ixy="0" ixz="0" iyy="0.001" iyz="0" izz="0.001" /></inertial><visual><origin rpy="0 0 0" xyz="0 0 0" /><geometry><sphere radius="0.048371464014053345" /></geometry><material name="color_right_shoulder_yaw_link_sphere2_0"><color rgba="0.5 0.1 0.5 1.0" /></material></visual><collision><origin rpy="0 0 0" xyz="0 0 0" /><geometry><sphere radius="0.048371464014053345" /></geometry><drake:proximity_properties><drake:rigid_hydroelastic /><drake:mesh_resolution_hint value="1.5" /><drake:hunt_crossley_dissipation value="1.25" /></drake:proximity_properties></collision></link><joint name="right_shoulder_yaw_link_to_right_shoulder_yaw_link_sphere2" type="fixed"><parent link="right_shoulder_yaw_link" /><child link="right_shoulder_yaw_link_sphere2" /><origin xyz="0.0031784051097929478 0.002170092659071088 -0.10315534472465515" rpy="0 0 0" /></joint><link name="right_shoulder_yaw_link_sphere3"><inertial><origin xyz="0 0 0" rpy="0 0 0" /><mass value="0.01" /><inertia ixx="0.001" ixy="0" ixz="0" iyy="0.001" iyz="0" izz="0.001" /></inertial><visual><origin rpy="0 0 0" xyz="0 0 0" /><geometry><sphere radius="0.04583407938480377" /></geometry><material name="color_right_shoulder_yaw_link_sphere3_0"><color rgba="0.5 0.1 0.5 1.0" /></material></visual><collision><origin rpy="0 0 0" xyz="0 0 0" /><geometry><sphere radius="0.04583407938480377" /></geometry><drake:proximity_properties><drake:rigid_hydroelastic /><drake:mesh_resolution_hint value="1.5" /><drake:hunt_crossley_dissipation value="1.25" /></drake:proximity_properties></collision></link><joint name="right_shoulder_yaw_link_to_right_shoulder_yaw_link_sphere3" type="fixed"><parent link="right_shoulder_yaw_link" /><child link="right_shoulder_yaw_link_sphere3" /><origin xyz="0.0009786337614059448 0.0006730608292855322 -0.03414745628833771" rpy="0 0 0" /></joint><link name="right_elbow_link_sphere1"><inertial><origin xyz="0 0 0" rpy="0 0 0" /><mass value="0.01" /><inertia ixx="0.001" ixy="0" ixz="0" iyy="0.001" iyz="0" izz="0.001" /></inertial><visual><origin rpy="0 0 0" xyz="0 0 0" /><geometry><sphere radius="0.0409969687461853" /></geometry><material name="color_right_elbow_link_sphere1_0"><color rgba="0.9 0.5 1.0 1.0" /></material></visual><collision><origin rpy="0 0 0" xyz="0 0 0" /><geometry><sphere radius="0.0409969687461853" /></geometry><drake:proximity_properties><drake:rigid_hydroelastic /><drake:mesh_resolution_hint value="1.5" /><drake:hunt_crossley_dissipation value="1.25" /></drake:proximity_properties></collision></link><joint name="right_elbow_link_to_right_elbow_link_sphere1" type="fixed"><parent link="right_elbow_link" /><child link="right_elbow_link_sphere1" /><origin xyz="0.08541678637266159 0.03081882745027542 -0.0092054083943367" rpy="0 0 0" /></joint><link name="right_elbow_link_sphere2"><inertial><origin xyz="0 0 0" rpy="0 0 0" /><mass value="0.01" /><inertia ixx="0.001" ixy="0" ixz="0" iyy="0.001" iyz="0" izz="0.001" /></inertial><visual><origin rpy="0 0 0" xyz="0 0 0" /><geometry><sphere radius="0.03794165328145027" /></geometry><material name="color_right_elbow_link_sphere2_0"><color rgba="0.9 0.5 1.0 1.0" /></material></visual><collision><origin rpy="0 0 0" xyz="0 0 0" /><geometry><sphere radius="0.03794165328145027" /></geometry><drake:proximity_properties><drake:rigid_hydroelastic /><drake:mesh_resolution_hint value="1.5" /><drake:hunt_crossley_dissipation value="1.25" /></drake:proximity_properties></collision></link><joint name="right_elbow_link_to_right_elbow_link_sphere2" type="fixed"><parent link="right_elbow_link" /><child link="right_elbow_link_sphere2" /><origin xyz="0.00833866186439991 0.013942179270088673 -0.001740008476190269" rpy="0 0 0" /></joint><link name="right_wrist_roll_link_sphere1"><inertial><origin xyz="0 0 0" rpy="0 0 0" /><mass value="0.01" /><inertia ixx="0.001" ixy="0" ixz="0" iyy="0.001" iyz="0" izz="0.001" /></inertial><visual><origin rpy="0 0 0" xyz="0 0 0" /><geometry><sphere radius="0.04306594654917717" /></geometry><material name="color_right_wrist_roll_link_sphere1_0"><color rgba="0.7 0.3 0.7 1.0" /></material></visual><collision><origin rpy="0 0 0" xyz="0 0 0" /><geometry><sphere radius="0.04306594654917717" /></geometry><drake:proximity_properties><drake:rigid_hydroelastic /><drake:mesh_resolution_hint value="1.5" /><drake:hunt_crossley_dissipation value="1.25" /></drake:proximity_properties></collision></link><joint name="right_wrist_roll_link_to_right_wrist_roll_link_sphere1" type="fixed"><parent link="right_wrist_roll_link" /><child link="right_wrist_roll_link_sphere1" /><origin xyz="0.041614972054958344 0.0007400974282063544 -5.998512642690912e-05" rpy="0 0 0" /></joint><link name="right_wrist_pitch_link_sphere1"><inertial><origin xyz="0 0 0" rpy="0 0 0" /><mass value="0.01" /><inertia ixx="0.001" ixy="0" ixz="0" iyy="0.001" iyz="0" izz="0.001" /></inertial><visual><origin rpy="0 0 0" xyz="0 0 0" /><geometry><sphere radius="0.035736940801143646" /></geometry><material name="color_right_wrist_pitch_link_sphere1_0"><color rgba="0.6 0.2 0.6 1.0" /></material></visual><collision><origin rpy="0 0 0" xyz="0 0 0" /><geometry><sphere radius="0.035736940801143646" /></geometry><drake:proximity_properties><drake:rigid_hydroelastic /><drake:mesh_resolution_hint value="1.5" /><drake:hunt_crossley_dissipation value="1.25" /></drake:proximity_properties></collision></link><joint name="right_wrist_pitch_link_to_right_wrist_pitch_link_sphere1" type="fixed"><parent link="right_wrist_pitch_link" /><child link="right_wrist_pitch_link_sphere1" /><origin xyz="0.01896509900689125 -1.5579093087580986e-05 0.0005533848307095468" rpy="0 0 0" /></joint><link name="right_wrist_yaw_link_sphere1"><inertial><origin xyz="0 0 0" rpy="0 0 0" /><mass value="0.01" /><inertia ixx="0.001" ixy="0" ixz="0" iyy="0.001" iyz="0" izz="0.001" /></inertial><visual><origin rpy="0 0 0" xyz="0 0 0" /><geometry><sphere radius="0.0401243194937706" /></geometry><material name="color_right_wrist_yaw_link_sphere1_0"><color rgba="0.4 0.1 0.4 1.0" /></material></visual><collision><origin rpy="0 0 0" xyz="0 0 0" /><geometry><sphere radius="0.0401243194937706" /></geometry><drake:proximity_properties><drake:rigid_hydroelastic /><drake:mesh_resolution_hint value="1.5" /><drake:hunt_crossley_dissipation value="1.25" /></drake:proximity_properties></collision></link><joint name="right_wrist_yaw_link_to_right_wrist_yaw_link_sphere1" type="fixed"><parent link="right_wrist_yaw_link" /><child link="right_wrist_yaw_link_sphere1" /><origin xyz="0.025164952501654625 -0.0002986877807416022 -8.146732579916716e-05" rpy="0 0 0" /></joint></robot>