<?xml version='1.0' encoding='utf-8'?>
<robot name="h1_2">

  <mujoco>
    <compiler meshdir="meshes" discardvisual="false" />
  </mujoco>

  <!-- [CAUTION] uncomment when convert to mujoco -->
  <!-- <link name="world"></link>
  <joint name="floating_base_joint" type="floating">
    <parent link="world"/>
    <child link="pelvis"/>
  </joint> -->

  <link name="pelvis">
    <inertial>
      <origin xyz="-0.0004 3.7E-05 -0.046864" rpy="0 0 0" />
      <mass value="5.983" />
      <inertia ixx="49168.411E-06" ixy="-19.869E-06" ixz="-48.460E-06" iyy="9025.844E-06" iyz="3.431E-06" izz="53155.891E-06" />
    </inertial>
    </link>

  <!-- L Leg -->
  <link name="left_hip_yaw_link">
    <inertial>
      <origin xyz="0 -0.026197 0.006647" rpy="0 0 0" />
      <mass value="2.829" />
      <inertia ixx="4553.605E-06" ixy="0.005E-06" ixz="0.817E-06" iyy="5688.730E-06" iyz="-345.157E-06" izz="3548.907E-06" />
    </inertial>
    </link>
  <joint name="left_hip_yaw_joint" type="revolute">
    <origin xyz="0 0.0875 -0.1632" rpy="0 0 0" />
    <parent link="pelvis" />
    <child link="left_hip_yaw_link" />
    <axis xyz="0 0 1" />
    <limit lower="-0.43" upper="0.43" effort="200" velocity="23" />
  </joint>
  <link name="left_hip_pitch_link">
    <inertial>
      <origin xyz="-0.00781 -0.004724 -0.000063" rpy="0 0 0" />
      <mass value="2.920" />
      <inertia ixx="5594.7E-06" ixy="143.308E-06" ixz="-11.847E-06" iyy="3862.581E-06" iyz="-9.607E-06" izz="4450.563E-06" />
    </inertial>
    </link>
  <joint name="left_hip_pitch_joint" type="revolute">
    <origin xyz="0 0.0755 0" rpy="0 0 0" />
    <parent link="left_hip_yaw_link" />
    <child link="left_hip_pitch_link" />
    <axis xyz="0 1 0" />
    <limit lower="-3.14" upper="2.5" effort="200" velocity="23" />
  </joint>
  <link name="left_hip_roll_link">
    <inertial>
      <origin xyz="0.004171 -0.008576 -0.194509" rpy="0 0 0" />
      <mass value="4.962" />
      <inertia ixx="46305.869E-06" ixy="-322.626E-06" ixz="-1199.703E-06" iyy="47955.402E-06" iyz="288.147E-06" izz="8914.518E-06" />
    </inertial>
    </link>
  <joint name="left_hip_roll_joint" type="revolute">
    <origin xyz="0 0 0" rpy="0 0 0" />
    <parent link="left_hip_pitch_link" />
    <child link="left_hip_roll_link" />
    <axis xyz="1 0 0" />
    <limit lower="-0.43" upper="3.14" effort="200" velocity="23" />
  </joint>
  <link name="left_knee_link">
    <inertial>
      <origin xyz="0.000179 0.000121 -0.168936" rpy="0 0 0" />
      <mass value="3.839" />
      <inertia ixx="39002.363e-6" ixy="-72.364e-6" ixz="-794.506e-6" iyy="39042.376e-6" iyz="-18.663e-6" izz="5029.829e-6" />
    </inertial>
    </link>
  <joint name="left_knee_joint" type="revolute">
    <origin xyz="0 0 -0.4" rpy="0 0 0" />
    <parent link="left_hip_roll_link" />
    <child link="left_knee_link" />
    <axis xyz="0 1 0" />
    <limit lower="-0.12" upper="2.19" effort="300" velocity="14" />
  </joint>
  <link name="left_ankle_pitch_link">
    <inertial>
      <origin xyz="-0.000294 0 -0.010794" rpy="0 0 0" />
      <mass value="0.102" />
      <inertia ixx="0.000023944" ixy="0" ixz="0.000000121" iyy="0.000021837" iyz="0" izz="0.000013414" />
    </inertial>
    </link>
  <joint name="left_ankle_pitch_joint" type="revolute">
    <origin xyz="0 0 -0.4" rpy="0 0 0" />
    <parent link="left_knee_link" />
    <child link="left_ankle_pitch_link" />
    <axis xyz="0 1 0" />
    <limit lower="-0.897334" upper="0.523598" effort="60" velocity="9" />
  </joint>
  <link name="left_ankle_roll_link">
    <inertial>
      <origin xyz="0.029589 0 -0.015973" rpy="0 0 0" />
      <mass value="0.747" />
      <inertia ixx="648.830e-6" ixy="0" ixz="158.380e-6" iyy="3435.339e-6" iyz="0" izz="3583.259e-6" />
    </inertial>
    </link>
  <joint name="left_ankle_roll_joint" type="revolute">
    <origin xyz="0 0 -0.02" rpy="0 0 0" />
    <parent link="left_ankle_pitch_link" />
    <child link="left_ankle_roll_link" />
    <axis xyz="1 0 0" />
    <limit lower="-0.261799" upper="0.261799" effort="40" velocity="9" />
  </joint>

  <!-- R Leg -->
  <link name="right_hip_yaw_link">
    <inertial>
      <origin xyz="0 0.026197 0.006647" rpy="0 0 0" />
      <mass value="2.829" />
      <inertia ixx="4553.605E-06" ixy="-0.005E-06" ixz="0.817E-06" iyy="5688.730E-06" iyz="345.157E-06" izz="3548.907E-06" />
    </inertial>
    </link>
  <joint name="right_hip_yaw_joint" type="revolute">
    <origin xyz="0 -0.0875 -0.1632" rpy="0 0 0" />
    <parent link="pelvis" />
    <child link="right_hip_yaw_link" />
    <axis xyz="0 0 1" />
    <limit lower="-0.43" upper="0.43" effort="200" velocity="23" />
  </joint>
  <link name="right_hip_pitch_link">
    <inertial>
      <origin xyz="-0.00781 0.004724 -0.000063" rpy="0 0 0" />
      <mass value="2.920" />
      <inertia ixx="5594.7E-06" ixy="-143.308E-06" ixz="-11.847E-06" iyy="3862.581E-06" iyz="9.607E-06" izz="4450.563E-06" />
    </inertial>
    </link>
  <joint name="right_hip_pitch_joint" type="revolute">
    <origin xyz="0 -0.0755 0" rpy="0 0 0" />
    <parent link="right_hip_yaw_link" />
    <child link="right_hip_pitch_link" />
    <axis xyz="0 1 0" />
    <limit lower="-3.14" upper="2.5" effort="200" velocity="23" />
  </joint>
  <link name="right_hip_roll_link">
    <inertial>
      <origin xyz="0.004171 0.008576 -0.194509" rpy="0 0 0" />
      <mass value="4.962" />
      <inertia ixx="46305.869E-06" ixy="322.626E-06" ixz="-1199.703E-06" iyy="47955.402E-06" iyz="-288.147E-06" izz="8914.518E-06" />
    </inertial>
    </link>
  <joint name="right_hip_roll_joint" type="revolute">
    <origin xyz="0 0 0" rpy="0 0 0" />
    <parent link="right_hip_pitch_link" />
    <child link="right_hip_roll_link" />
    <axis xyz="1 0 0" />
    <limit lower="-3.14" upper="0.43" effort="200" velocity="23" />
  </joint>
  <link name="right_knee_link">
    <inertial>
      <origin xyz="0.000179 -0.000121 -0.168936" rpy="0 0 0" />
      <mass value="3.839" />
      <inertia ixx="39002.363e-6" ixy="72.364e-6" ixz="-794.506e-6" iyy="39042.376e-6" iyz="18.663e-6" izz="5029.829e-6" />
    </inertial>
    </link>
  <joint name="right_knee_joint" type="revolute">
    <origin xyz="0 0 -0.4" rpy="0 0 0" />
    <parent link="right_hip_roll_link" />
    <child link="right_knee_link" />
    <axis xyz="0 1 0" />
    <limit lower="-0.12" upper="2.19" effort="300" velocity="14" />
  </joint>
  <link name="right_ankle_pitch_link">
    <inertial>
      <origin xyz="-0.000294 0 -0.010794" rpy="0 0 0" />
      <mass value="0.102" />
      <inertia ixx="0.000023944" ixy="0" ixz="0.000000121" iyy="0.000021837" iyz="0" izz="0.000013414" />
    </inertial>
    </link>
  <joint name="right_ankle_pitch_joint" type="revolute">
    <origin xyz="0 0 -0.4" rpy="0 0 0" />
    <parent link="right_knee_link" />
    <child link="right_ankle_pitch_link" />
    <axis xyz="0 1 0" />
    <limit lower="-0.897334" upper="0.523598" effort="60" velocity="9" />
  </joint>
  <link name="right_ankle_roll_link">
    <inertial>
      <origin xyz="0.029589 0 -0.015973" rpy="0 0 0" />
      <mass value="0.747" />
      <inertia ixx="648.830e-6" ixy="0" ixz="158.380e-6" iyy="3435.339e-6" iyz="0" izz="3583.259e-6" />
    </inertial>
    </link>
  <joint name="right_ankle_roll_joint" type="revolute">
    <origin xyz="0 0 -0.02" rpy="0 0 0" />
    <parent link="right_ankle_pitch_link" />
    <child link="right_ankle_roll_link" />
    <axis xyz="1 0 0" />
    <limit lower="-0.261799" upper="0.261799" effort="40" velocity="9" />
  </joint>

  <!-- Torso -->
  <link name="torso_link">
    <inertial>
      <origin xyz="0.000489 0.002797 0.20484" rpy="0 0 0" />
      <mass value="17.789" />
      <inertia ixx="0.4873" ixy="-0.00053763" ixz="0.0020276" iyy="0.40963" iyz="-0.00074582" izz="0.12785" />
    </inertial>
    </link>
  <joint name="torso_joint" type="revolute">
    <origin xyz="0 0 0" rpy="0 0 0" />
    <parent link="pelvis" />
    <child link="torso_link" />
    <axis xyz="0 0 1" />
    <limit lower="-2.35" upper="2.35" effort="200" velocity="23" />
  </joint>

  <!-- L arm -->
  <link name="left_shoulder_pitch_link">
    <inertial>
      <origin xyz="0.003053 0.06042 -0.0059" rpy="0 0 0" />
      <mass value="1.327" />
      <inertia ixx="0.00058661" ixy="-2.0157E-05" ixz="2.985E-06" iyy="0.0003989" iyz="2.238E-05" izz="0.00052936" />
    </inertial>
    </link>
  <joint name="left_shoulder_pitch_joint" type="revolute">
    <origin xyz="0 0.14806 0.42333" rpy="0.2618 0 0" />
    <parent link="torso_link" />
    <child link="left_shoulder_pitch_link" />
    <axis xyz="0 1 0" />
    <limit lower="-3.14" upper="1.57" effort="40" velocity="9" />
  </joint>
  <link name="left_shoulder_roll_link">
    <inertial>
      <origin xyz="-0.030932 -1E-06 -0.10609" rpy="0 0 0" />
      <mass value="1.393" />
      <inertia ixx="0.0018408" ixy="3.98E-07" ixz="-0.00048324" iyy="0.001934638" iyz="1.61E-07" izz="0.000617733" />
    </inertial>
    </link>
  <joint name="left_shoulder_roll_joint" type="revolute">
    <origin xyz="0.0342 0.061999 -0.0060011" rpy="-0.2618 0 0" />
    <parent link="left_shoulder_pitch_link" />
    <child link="left_shoulder_roll_link" />
    <axis xyz="1 0 0" />
    <limit lower="-0.38" upper="3.4" effort="40" velocity="9" />
  </joint>
  <link name="left_shoulder_yaw_link">
    <inertial>
      <origin xyz="0.004583 0.001128 -0.001128" rpy="0 0 0" />
      <mass value="1.505" />
      <inertia ixx="0.004199" ixy="-1.7786E-05" ixz="0.00018372" iyy="0.0043139" iyz="9.278E-05" izz="0.00065755" />
    </inertial>
    </link>
  <joint name="left_shoulder_yaw_joint" type="revolute">
    <origin xyz="-0.0342 0 -0.1456" rpy="0 0 0" />
    <parent link="left_shoulder_roll_link" />
    <child link="left_shoulder_yaw_link" />
    <axis xyz="0 0 1" />
    <limit lower="-2.66" upper="3.01" effort="18" velocity="20" />
  </joint>
  <link name="left_elbow_link">
    <inertial>
      <origin xyz="0.077092 -0.028751 -0.009714 " rpy="0 0 0" />
      <mass value="0.691" />
      <inertia ixx="0.000318491" ixy="0.000224554" ixz="6.62076E-05" iyy="0.000861224" iyz="-2.3329E-05" izz="0.000897899" />
    </inertial>
    </link>
  <joint name="left_elbow_joint" type="revolute">
    <origin xyz="0.006 0.0329 -0.182" rpy="0 0 0" />
    <parent link="left_shoulder_yaw_link" />
    <child link="left_elbow_link" />
    <axis xyz="0 1 0" />
    <limit lower="-0.95" upper="3.18" effort="18" velocity="20" />
  </joint>

  <link name="left_wrist_roll_link">
    <inertial>
      <origin xyz="0.035281 -0.002320 0.000337" rpy="0 0 0" />
      <mass value="0.683" />
      <inertia ixx="0.000313275" ixy="0.000016521" ixz="-0.000002501" iyy="0.000310412" iyz="0.000005435" izz="0.000345998" />
    </inertial>
    </link>
  <joint name="left_wrist_roll_joint" type="revolute">
    <origin xyz="0.121 -0.0329 -0.011" rpy="0 0 0" />
    <parent link="left_elbow_link" />
    <child link="left_wrist_roll_link" />
    <axis xyz="1 0 0" />
    <limit lower="-3.01" upper="2.75" effort="19" velocity="31.4" />
  </joint>

  <link name="left_wrist_pitch_link">
    <inertial>
      <origin xyz="0.020395 0.000036 -0.002973" rpy="0 0 0" />
      <mass value="0.484" />
      <inertia ixx="0.000071364" ixy="0.000000308" ixz="0.000001485" iyy="0.000069915" iyz="-0.000000088" izz="0.000070702" />
    </inertial>
    </link>
  <joint name="left_wrist_pitch_joint" type="revolute">
    <origin xyz="0.087 0 0" rpy="0 0 0" />
    <parent link="left_wrist_roll_link" />
    <child link="left_wrist_pitch_link" />
    <axis xyz="0 1 0" />
    <limit lower="-0.4625" upper="0.4625" effort="19" velocity="31.4" />
  </joint>
  <link name="left_wrist_yaw_link">
    <inertial>
      <origin xyz="0.027967 0.000096 0.000739" rpy="0 0 0" />
      <mass value="0.124" />
      <inertia ixx="137.3e-6" ixy="-0.171e-6" ixz="2.942e-6" iyy="169.998e-6" iyz="-0.025e-6" izz="84.808e-6" />
    </inertial>
    <!-- <collision>
      <origin xyz="0 0 0" rpy="0 0 0"/>
      <geometry>
        <mesh filename="meshes/wrist_yaw_link.STL"/>
      </geometry>
    </collision> -->
  </link>
  <joint name="left_wrist_yaw_joint" type="revolute">
    <origin xyz="0.020 0 0" rpy="0 0 0" />
    <parent link="left_wrist_pitch_link" />
    <child link="left_wrist_yaw_link" />
    <axis xyz="0 0 1" />
    <limit lower="-1.27" upper="1.27" effort="19" velocity="31.4" />
  </joint>

  <!-- R arm -->
  <link name="right_shoulder_pitch_link">
    <inertial>
      <origin xyz="0.003053 -0.06042 -0.0059" rpy="0 0 0" />
      <mass value="1.327" />
      <inertia ixx="0.00058661" ixy="2.0157E-05" ixz="2.985E-06" iyy="0.0003989" iyz="-2.238E-05" izz="0.00052936" />
    </inertial>
    </link>
  <joint name="right_shoulder_pitch_joint" type="revolute">
    <origin xyz="0 -0.14806 0.42333" rpy="-0.2618 0 0" />
    <parent link="torso_link" />
    <child link="right_shoulder_pitch_link" />
    <axis xyz="0 1 0" />
    <limit lower="-3.14" upper="1.57" effort="40" velocity="9" />
  </joint>
  <link name="right_shoulder_roll_link">
    <inertial>
      <origin xyz="-0.030932 1E-06 -0.10609" rpy="0 0 0" />
      <mass value="1.393" />
      <inertia ixx="0.0018408" ixy="-3.98E-07" ixz="-0.00048324" iyy="0.001934638" iyz="-1.61E-07" izz="0.000617733" />
    </inertial>
    </link>
  <joint name="right_shoulder_roll_joint" type="revolute">
    <origin xyz="0.0342 -0.061999 -0.0060011" rpy="0.2618 0 0" />
    <parent link="right_shoulder_pitch_link" />
    <child link="right_shoulder_roll_link" />
    <axis xyz="1 0 0" />
    <limit lower="-3.4" upper="0.38" effort="40" velocity="9" />
  </joint>
  <link name="right_shoulder_yaw_link">
    <inertial>
      <origin xyz="0.004583 -0.001128 -0.001128" rpy="0 0 0" />
      <mass value="1.505" />
      <inertia ixx="0.004199" ixy="1.7786E-05" ixz="0.00018372" iyy="0.0043139" iyz="-9.278E-05" izz="0.00065755" />

    </inertial>
    </link>
  <joint name="right_shoulder_yaw_joint" type="revolute">
    <origin xyz="-0.0342 0 -0.1456" rpy="0 0 0" />
    <parent link="right_shoulder_roll_link" />
    <child link="right_shoulder_yaw_link" />
    <axis xyz="0 0 1" />
    <limit lower="-3.01" upper="2.66" effort="18" velocity="20" />
  </joint>
  <link name="right_elbow_link">
    <inertial>
      <origin xyz="0.077092 0.028751 -0.009714 " rpy="0 0 0" />
      <mass value="0.691" />
      <inertia ixx="0.000318491" ixy="-0.000224554" ixz="6.62076E-05" iyy="0.000861224" iyz="2.3329E-05" izz="0.000897899" />
    </inertial>
    </link>
  <joint name="right_elbow_joint" type="revolute">
    <origin xyz="0.006 -0.0329 -0.182" rpy="0 0 0" />
    <parent link="right_shoulder_yaw_link" />
    <child link="right_elbow_link" />
    <axis xyz="0 1 0" />
    <limit lower="-0.95" upper="3.18" effort="18" velocity="20" />
  </joint>

  <link name="right_wrist_roll_link">
    <inertial>
      <origin xyz="0.035281 -0.002320 0.000337" rpy="0 0 0" />
      <mass value="0.683" />
      <inertia ixx="0.000313275" ixy="0.000016521" ixz="-0.000002501" iyy="0.000310412" iyz="0.000005435" izz="0.000345998" />
    </inertial>
    </link>
  <joint name="right_wrist_roll_joint" type="revolute">
    <origin xyz="0.121 0.0329 -0.011" rpy="0 0 0" />
    <parent link="right_elbow_link" />
    <child link="right_wrist_roll_link" />
    <axis xyz="1 0 0" />
    <limit lower="-2.75" upper="3.01" effort="19" velocity="31.4" />
  </joint>

  <link name="right_wrist_pitch_link">
    <inertial>
      <origin xyz="0.020395 0.000036 -0.002973" rpy="0 0 0" />
      <mass value="0.484" />
      <inertia ixx="0.000071364" ixy="0.000000308" ixz="0.000001485" iyy="0.000069915" iyz="-0.000000088" izz="0.000070702" />
    </inertial>
    </link>
  <joint name="right_wrist_pitch_joint" type="revolute">
    <origin xyz="0.087 0 0" rpy="0 0 0" />
    <parent link="right_wrist_roll_link" />
    <child link="right_wrist_pitch_link" />
    <axis xyz="0 1 0" />
    <limit lower="-0.4625" upper="0.4625" effort="19" velocity="31.4" />
  </joint>
  <link name="right_wrist_yaw_link">
    <inertial>
      <origin xyz="0.027967 -0.000096 0.000739" rpy="0 0 0" />
      <mass value="0.124" />
      <inertia ixx="137.3e-6" ixy="0.171e-6" ixz="2.942e-6" iyy="169.998e-6" iyz="0.025e-6" izz="84.808e-6" />
    </inertial>
    <!-- <collision>
      <origin xyz="0 0 0" rpy="0 0 0"/>
      <geometry>
        <mesh filename="meshes/wrist_yaw_link.STL"/>
      </geometry>
    </collision> -->
  </link>
  <joint name="right_wrist_yaw_joint" type="revolute">
    <origin xyz="0.020 0 0" rpy="0 0 0" />
    <parent link="right_wrist_pitch_link" />
    <child link="right_wrist_yaw_link" />
    <axis xyz="0 0 1" />
    <limit lower="-1.27" upper="1.27" effort="19" velocity="31.4" />
  </joint>

  <!-- LOGO -->
  <link name="logo_link">
    </link>
  <joint name="logo_joint" type="fixed">
    <origin xyz="0 0 0" rpy="0 0 0" />
    <parent link="torso_link" />
    <child link="logo_link" />
    <axis xyz="0 0 0" />
  </joint>

  <!-- IMU -->
  <link name="imu_link" />
  <joint name="imu_joint" type="fixed">
    <origin xyz="-0.04452 -0.01891 0.27756" rpy="0 0 0" />
    <parent link="torso_link" />
    <child link="imu_link" />
  </joint>

  <!-- Camera&Lidar -->
  <!--
  <link name="camera_link"></link>
  <joint name="camera_joint" type="fixed">
    <origin xyz="0.11109 0.01750 0.68789" rpy="0 0.8859291283123216 0"/>
    <parent link="torso_link"/>
    <child link="camera_link"/>
  </joint>
  <link name="lidar_link"></link>
  <joint name="lidar_joint" type="fixed">
    <origin xyz="0.04874 0 0.67980" rpy="0 0.24015730507441985 0"/>
    <parent link="torso_link"/>
    <child link="lidar_link"/>
  </joint>
  -->

  <!-- LiDAR -->
  <link name="lidar_link" />
  <joint name="lidar_joint" type="fixed">
    <origin xyz="0.04874 0 0.679808" rpy="0 -2.90143535 0" />
    <parent link="torso_link" />
    <child link="lidar_link" />
  </joint>

  <!-- Head Camera -->
  <link name="head_camera_link" />
  <joint name="head_camera_joint" type="fixed">
    <origin xyz="0.11109 0.01750 0.68789" rpy="-2.45672546 0 -1.5708" />
    <parent link="torso_link" />
    <child link="head_camera_link" />
  </joint>

  <!-- Left Wrist Camera -->
  <link name="left_hand_camera_link" />
  <joint name="left_hand_camera_joint" type="fixed">
    <origin xyz="0 0.04 0" rpy="0 1.5708 0" />
    <parent link="left_wrist_yaw_link" />
    <child link="left_hand_camera_link" />
  </joint>

  <!-- Right Wrist Camera -->
  <link name="right_hand_camera_link" />
  <joint name="right_hand_camera_joint" type="fixed">
    <origin xyz="0 -0.04 0" rpy="-3.1415 -1.5708 0" />
    <parent link="right_wrist_yaw_link" />
    <child link="right_hand_camera_link" />
  </joint>

  <!-- L Gripper -->
  <joint name="L_base_link_joint" type="fixed">
    <origin xyz="0.054 0 0" rpy="0 0 1.5707963267948966192313216916398" />
    <parent link="left_wrist_yaw_link" />
    <child link="L_hand_base_link" />
  </joint>
  <link name="L_hand_base_link">
    <inertial>
      <origin xyz="-0.002551 -0.066047 -0.0019357" rpy="0 0 0" />
      <mass value="0.14143" />
      <inertia ixx="0.0001234" ixy="2.1995E-06" ixz="-1.7694E-06" iyy="8.3835E-05" iyz="1.5968E-06" izz="7.7231E-05" />
    </inertial>
    </link>
  <link name="L_thumb_proximal_base">
    <inertial>
      <origin xyz="0.0048817 0.00038782 -0.00722" rpy="0 0 0" />
      <mass value="0.0018869" />
      <inertia ixx="5.5158E-08" ixy="-1.1803E-08" ixz="-4.6743E-09" iyy="8.2164E-08" iyz="-1.3521E-09" izz="6.7434E-08" />
    </inertial>
    </link>
  <joint name="L_thumb_proximal_yaw_joint" type="revolute">
    <origin xyz="-0.01696 -0.0691 0.02045" rpy="1.5708 -1.5708 0" />
    <parent link="L_hand_base_link" />
    <child link="L_thumb_proximal_base" />
    <axis xyz="0 0 1" />
    <limit lower="-0.1" upper="1.3" effort="1" velocity="0.5" />
  </joint>
  <link name="L_thumb_proximal">
    <inertial>
      <origin xyz="0.021936 -0.01279 -0.0080386" rpy="0 0 0" />
      <mass value="0.0066101" />
      <inertia ixx="1.5693E-06" ixy="7.8339E-07" ixz="8.5959E-10" iyy="1.7356E-06" iyz="1.0378E-09" izz="2.787E-06" />
    </inertial>
    </link>
  <joint name="L_thumb_proximal_pitch_joint" type="revolute">
    <origin xyz="0.0099867 0.0098242 -0.0089" rpy="-1.5708 0 0.16939" />
    <parent link="L_thumb_proximal_base" />
    <child link="L_thumb_proximal" />
    <axis xyz="0 0 -1" />
    <limit lower="-0.1" upper="0.6" effort="1" velocity="0.5" />
  </joint>
  <link name="L_thumb_intermediate">
    <inertial>
      <origin xyz="0.0095531 0.0016282 -0.0072002" rpy="0 0 0" />
      <mass value="0.0037844" />
      <inertia ixx="3.6981E-07" ixy="9.8603E-08" ixz="-2.8173E-12" iyy="3.2395E-07" iyz="-2.8028E-12" izz="4.6532E-07" />
    </inertial>
    </link>
  <joint name="L_thumb_intermediate_joint" type="revolute">
    <origin xyz="0.04407 -0.034553 -0.0008" rpy="0 0 0" />
    <parent link="L_thumb_proximal" />
    <child link="L_thumb_intermediate" />
    <axis xyz="0 0 -1" />
    <limit lower="0" upper="0.8" effort="1" velocity="0.5" />
    <mimic joint="L_thumb_proximal_pitch_joint" multiplier="1.6" offset="0" />
  </joint>
  <link name="L_thumb_distal">
    <inertial>
      <origin xyz="0.0092888 -0.004953 -0.0060033" rpy="0 0 0" />
      <mass value="0.003344" />
      <inertia ixx="1.3632E-07" ixy="5.6787E-08" ixz="-9.1939E-11" iyy="1.4052E-07" iyz="1.2145E-10" izz="2.0026E-07" />
    </inertial>
    </link>
  <joint name="L_thumb_distal_joint" type="revolute">
    <origin xyz="0.020248 -0.010156 -0.0012" rpy="0 0 0" />
    <parent link="L_thumb_intermediate" />
    <child link="L_thumb_distal" />
    <axis xyz="0 0 -1" />
    <limit lower="0" upper="1.2" effort="1" velocity="0.5" />
    <mimic joint="L_thumb_proximal_pitch_joint" multiplier="2.4" offset="0" />
  </joint>
  <link name="L_index_proximal">
    <inertial>
      <origin xyz="0.0012971 -0.011934 -0.0059998" rpy="0 0 0" />
      <mass value="0.0042405" />
      <inertia ixx="6.6215E-07" ixy="1.8442E-08" ixz="1.3746E-12" iyy="2.1167E-07" iyz="-1.4773E-11" izz="6.9402E-07" />
    </inertial>
    </link>
  <joint name="L_index_proximal_joint" type="revolute">
    <origin xyz="0.00028533 -0.13653 0.032268" rpy="-0.034907 0 0" />
    <parent link="L_hand_base_link" />
    <child link="L_index_proximal" />
    <axis xyz="0 0 -1" />
    <limit lower="0" upper="1.7" effort="1" velocity="0.5" />
  </joint>
  <link name="L_index_intermediate">
    <inertial>
      <origin xyz="0.0021753 -0.019567 -0.005" rpy="0 0 0" />
      <mass value="0.0045682" />
      <inertia ixx="7.6284E-07" ixy="-8.063E-08" ixz="3.6797E-13" iyy="9.4308E-08" iyz="1.5743E-13" izz="7.8176E-07" />
    </inertial>
    </link>
  <joint name="L_index_intermediate_joint" type="revolute">
    <origin xyz="-0.0024229 -0.032041 -0.001" rpy="0 0 0" />
    <parent link="L_index_proximal" />
    <child link="L_index_intermediate" />
    <axis xyz="0 0 -1" />
    <limit lower="0" upper="1.7" effort="1" velocity="0.5" />
    <mimic joint="L_index_proximal_joint" multiplier="1" offset="0" />
  </joint>
  <link name="L_middle_proximal">
    <inertial>
      <origin xyz="0.0012971 -0.011934 -0.0059999" rpy="0 0 0" />
      <mass value="0.0042405" />
      <inertia ixx="6.6215E-07" ixy="1.8442E-08" ixz="1.2299E-12" iyy="2.1167E-07" iyz="-1.4484E-11" izz="6.9402E-07" />
    </inertial>
    </link>
  <joint name="L_middle_proximal_joint" type="revolute">
    <origin xyz="0.00028533 -0.1371 0.01295" rpy="0 0 0" />
    <parent link="L_hand_base_link" />
    <child link="L_middle_proximal" />
    <axis xyz="0 0 -1" />
    <limit lower="0" upper="1.7" effort="1" velocity="0.5" />
  </joint>
  <link name="L_middle_intermediate">
    <inertial>
      <origin xyz="0.001921 -0.020796 -0.0049999" rpy="0 0 0" />
      <mass value="0.0050397" />
      <inertia ixx="9.5823E-07" ixy="-1.1425E-07" ixz="-2.4186E-12" iyy="1.0646E-07" iyz="3.6974E-12" izz="9.8385E-07" />
    </inertial>
    </link>
  <joint name="L_middle_intermediate_joint" type="revolute">
    <origin xyz="-0.0024229 -0.032041 -0.001" rpy="0 0 0" />
    <parent link="L_middle_proximal" />
    <child link="L_middle_intermediate" />
    <axis xyz="0 0 -1" />
    <limit lower="0" upper="1.7" effort="1" velocity="0.5" />
    <mimic joint="L_middle_proximal_joint" multiplier="1" offset="0" />
  </joint>
  <link name="L_ring_proximal">
    <inertial>
      <origin xyz="0.0012971 -0.011934 -0.0059999" rpy="0 0 0" />
      <mass value="0.0042405" />
      <inertia ixx="6.6215E-07" ixy="1.8442E-08" ixz="9.6052E-13" iyy="2.1167E-07" iyz="-1.4124E-11" izz="6.9402E-07" />
    </inertial>
    </link>
  <joint name="L_ring_proximal_joint" type="revolute">
    <origin xyz="0.00028533 -0.13691 -0.0062872" rpy="0.05236 0 0" />
    <parent link="L_hand_base_link" />
    <child link="L_ring_proximal" />
    <axis xyz="0 0 -1" />
    <limit lower="0" upper="1.7" effort="1" velocity="0.5" />
  </joint>
  <link name="L_ring_intermediate">
    <inertial>
      <origin xyz="0.0021753 -0.019567 -0.005" rpy="0 0 0" />
      <mass value="0.0045682" />
      <inertia ixx="7.6285E-07" ixy="-8.0631E-08" ixz="3.3472E-14" iyy="9.4308E-08" iyz="-4.4773E-13" izz="7.8176E-07" />
    </inertial>
    </link>
  <joint name="L_ring_intermediate_joint" type="revolute">
    <origin xyz="-0.0024229 -0.032041 -0.001" rpy="0 0 0" />
    <parent link="L_ring_proximal" />
    <child link="L_ring_intermediate" />
    <axis xyz="0 0 -1" />
    <limit lower="0" upper="1.7" effort="1" velocity="0.5" />
    <mimic joint="L_ring_proximal_joint" multiplier="1" offset="0" />
  </joint>
  <link name="L_pinky_proximal">
    <inertial>
      <origin xyz="0.0012971 -0.011934 -0.0059999" rpy="0 0 0" />
      <mass value="0.0042405" />
      <inertia ixx="6.6215E-07" ixy="1.8442E-08" ixz="1.0279E-12" iyy="2.1167E-07" iyz="-1.4277E-11" izz="6.9402E-07" />
    </inertial>
    </link>
  <joint name="L_pinky_proximal_joint" type="revolute">
    <origin xyz="0.00028533 -0.13571 -0.025488" rpy="0.10472 0 0" />
    <parent link="L_hand_base_link" />
    <child link="L_pinky_proximal" />
    <axis xyz="0 0 -1" />
    <limit lower="0" upper="1.7" effort="1" velocity="0.5" />
  </joint>
  <link name="L_pinky_intermediate">
    <inertial>
      <origin xyz="0.0024788 -0.016208 -0.0050001" rpy="0 0 0" />
      <mass value="0.0036036" />
      <inertia ixx="4.3923E-07" ixy="-4.1355E-08" ixz="1.2263E-12" iyy="7.0315E-08" iyz="3.1311E-12" izz="4.4881E-07" />
    </inertial>
    </link>
  <joint name="L_pinky_intermediate_joint" type="revolute">
    <origin xyz="-0.0024229 -0.032041 -0.001" rpy="0 0 0" />
    <parent link="L_pinky_proximal" />
    <child link="L_pinky_intermediate" />
    <axis xyz="0 0 -1" />
    <limit lower="0" upper="1.7" effort="1" velocity="0.5" />
    <mimic joint="L_pinky_proximal_joint" multiplier="1" offset="0" />
  </joint>

  <!-- R Gripper -->
  <joint name="R_base_link_joint" type="fixed">
    <origin xyz="0.054 0 0" rpy="3.1415926535897932384626433832795 0 -1.5707963267948966192313216916398" />
    <parent link="right_wrist_yaw_link" />
    <child link="R_hand_base_link" />
  </joint>
  <link name="R_hand_base_link">
    <inertial>
      <origin xyz="-0.0025264 -0.066047 0.0019598" rpy="0 0 0" />
      <mass value="0.14143" />
      <inertia ixx="0.00012281" ixy="2.1711E-06" ixz="1.7709E-06" iyy="8.3832E-05" iyz="-1.6551E-06" izz="7.6663E-05" />
    </inertial>
    </link>
  <link name="R_thumb_proximal_base">
    <inertial>
      <origin xyz="-0.0048064 0.0009382 -0.00757" rpy="0 0 0" />
      <mass value="0.0018869" />
      <inertia ixx="5.816E-08" ixy="1.4539E-08" ixz="4.491E-09" iyy="7.9161E-08" iyz="-1.8727E-09" izz="6.7433E-08" />
    </inertial>
    </link>
  <joint name="R_thumb_proximal_yaw_joint" type="revolute">
    <origin xyz="-0.01696 -0.0691 -0.02045" rpy="1.5708 -1.5708 0" />
    <parent link="R_hand_base_link" />
    <child link="R_thumb_proximal_base" />
    <axis xyz="0 0 -1" />
    <limit lower="-0.1" upper="1.3" effort="1" velocity="0.5" />
  </joint>
  <link name="R_thumb_proximal">
    <inertial>
      <origin xyz="0.021932 0.012785 -0.0080386" rpy="0 0 0" />
      <mass value="0.0066075" />
      <inertia ixx="1.5686E-06" ixy="-7.8296E-07" ixz="8.9143E-10" iyy="1.7353E-06" iyz="-1.0191E-09" izz="2.786E-06" />
    </inertial>
    </link>
  <joint name="R_thumb_proximal_pitch_joint" type="revolute">
    <origin xyz="-0.0088099 0.010892 -0.00925" rpy="1.5708 0 2.8587" />
    <parent link="R_thumb_proximal_base" />
    <child link="R_thumb_proximal" />
    <axis xyz="0 0 1" />
    <limit lower="-0.1" upper="0.6" effort="1" velocity="0.5" />
  </joint>
  <link name="R_thumb_intermediate">
    <inertial>
      <origin xyz="0.0095544 -0.0016282 -0.0071997" rpy="0 0 0" />
      <mass value="0.0037847" />
      <inertia ixx="3.6981E-07" ixy="-9.8581E-08" ixz="-4.7469E-12" iyy="3.2394E-07" iyz="1.0939E-12" izz="4.6531E-07" />
    </inertial>
    </link>
  <joint name="R_thumb_intermediate_joint" type="revolute">
    <origin xyz="0.04407 0.034553 -0.0008" rpy="0 0 0" />
    <parent link="R_thumb_proximal" />
    <child link="R_thumb_intermediate" />
    <axis xyz="0 0 1" />
    <limit lower="0" upper="0.8" effort="1" velocity="0.5" />
    <mimic joint="R_thumb_proximal_pitch_joint" multiplier="1.6" offset="0" />
  </joint>
  <link name="R_thumb_distal">
    <inertial>
      <origin xyz="0.0092888 0.0049529 -0.0060033" rpy="0 0 0" />
      <mass value="0.0033441" />
      <inertia ixx="1.3632E-07" ixy="-5.6788E-08" ixz="-9.2764E-11" iyy="1.4052E-07" iyz="-1.2283E-10" izz="2.0026E-07" />
    </inertial>
    </link>
  <joint name="R_thumb_distal_joint" type="revolute">
    <origin xyz="0.020248 0.010156 -0.0012" rpy="0 0 0" />
    <parent link="R_thumb_intermediate" />
    <child link="R_thumb_distal" />
    <axis xyz="0 0 1" />
    <limit lower="0" upper="1.2" effort="1" velocity="0.5" />
    <mimic joint="R_thumb_proximal_pitch_joint" multiplier="2.4" offset="0" />
  </joint>
  <link name="R_index_proximal">
    <inertial>
      <origin xyz="0.0012259 0.011942 -0.0060001" rpy="0 0 0" />
      <mass value="0.0042403" />
      <inertia ixx="6.6232E-07" ixy="-1.5775E-08" ixz="1.8515E-12" iyy="2.1146E-07" iyz="-5.0828E-12" izz="6.9398E-07" />
    </inertial>
    </link>
  <joint name="R_index_proximal_joint" type="revolute">
    <origin xyz="0.00028533 -0.13653 -0.032268" rpy="-3.1067 0 0" />
    <parent link="R_hand_base_link" />
    <child link="R_index_proximal" />
    <axis xyz="0 0 1" />
    <limit lower="0" upper="1.7" effort="1" velocity="0.5" />
  </joint>
  <link name="R_index_intermediate">
    <inertial>
      <origin xyz="0.0019697 0.019589 -0.005" rpy="0 0 0" />
      <mass value="0.0045683" />
      <inertia ixx="7.6111E-07" ixy="8.7637E-08" ixz="-3.7751E-13" iyy="9.6076E-08" iyz="9.9444E-13" izz="7.8179E-07" />
    </inertial>
    </link>
  <joint name="R_index_intermediate_joint" type="revolute">
    <origin xyz="-0.0026138 0.032026 -0.001" rpy="0 0 0" />
    <parent link="R_index_proximal" />
    <child link="R_index_intermediate" />
    <axis xyz="0 0 1" />
    <limit lower="0" upper="1.7" effort="1" velocity="0.5" />
    <mimic joint="R_index_proximal_joint" multiplier="1" offset="0" />
  </joint>
  <link name="R_middle_proximal">
    <inertial>
      <origin xyz="0.001297 0.011934 -0.0060001" rpy="0 0 0" />
      <mass value="0.0042403" />
      <inertia ixx="6.6211E-07" ixy="-1.8461E-08" ixz="1.8002E-12" iyy="2.1167E-07" iyz="-6.6808E-12" izz="6.9397E-07" />
    </inertial>
    </link>
  <joint name="R_middle_proximal_joint" type="revolute">
    <origin xyz="0.00028533 -0.1371 -0.01295" rpy="-3.1416 0 0" />
    <parent link="R_hand_base_link" />
    <child link="R_middle_proximal" />
    <axis xyz="0 0 1" />
    <limit lower="0" upper="1.7" effort="1" velocity="0.5" />
  </joint>
  <link name="R_middle_intermediate">
    <inertial>
      <origin xyz="0.001921 0.020796 -0.005" rpy="0 0 0" />
      <mass value="0.0050396" />
      <inertia ixx="9.5822E-07" ixy="1.1425E-07" ixz="-2.4791E-12" iyy="1.0646E-07" iyz="5.9173E-12" izz="9.8384E-07" />
    </inertial>
    </link>
  <joint name="R_middle_intermediate_joint" type="revolute">
    <origin xyz="-0.0024229 0.032041 -0.001" rpy="0 0 0" />
    <parent link="R_middle_proximal" />
    <child link="R_middle_intermediate" />
    <axis xyz="0 0 1" />
    <limit lower="0" upper="1.7" effort="1" velocity="0.5" />
    <mimic joint="R_middle_proximal_joint" multiplier="1" offset="0" />
  </joint>
  <link name="R_ring_proximal">
    <inertial>
      <origin xyz="0.001297 0.011934 -0.0060002" rpy="0 0 0" />
      <mass value="0.0042403" />
      <inertia ixx="6.6211E-07" ixy="-1.8461E-08" ixz="1.5793E-12" iyy="2.1167E-07" iyz="-6.6868E-12" izz="6.9397E-07" />
    </inertial>
    </link>
  <joint name="R_ring_proximal_joint" type="revolute">
    <origin xyz="0.00028533 -0.13691 0.0062872" rpy="3.0892 0 0" />
    <parent link="R_hand_base_link" />
    <child link="R_ring_proximal" />
    <axis xyz="0 0 1" />
    <limit lower="0" upper="1.7" effort="1" velocity="0.5" />
  </joint>
  <link name="R_ring_intermediate">
    <inertial>
      <origin xyz="0.0021753 0.019567 -0.005" rpy="0 0 0" />
      <mass value="0.0045683" />
      <inertia ixx="7.6286E-07" ixy="8.0635E-08" ixz="-6.1562E-13" iyy="9.431E-08" iyz="5.8619E-13" izz="7.8177E-07" />
    </inertial>
    </link>
  <joint name="R_ring_intermediate_joint" type="revolute">
    <origin xyz="-0.0024229 0.032041 -0.001" rpy="0 0 0" />
    <parent link="R_ring_proximal" />
    <child link="R_ring_intermediate" />
    <axis xyz="0 0 1" />
    <limit lower="0" upper="1.7" effort="1" velocity="0.5" />
    <mimic joint="R_ring_proximal_joint" multiplier="1" offset="0" />
  </joint>
  <link name="R_pinky_proximal">
    <inertial>
      <origin xyz="0.001297 0.011934 -0.0060001" rpy="0 0 0" />
      <mass value="0.0042403" />
      <inertia ixx="6.6211E-07" ixy="-1.8461E-08" ixz="1.6907E-12" iyy="2.1167E-07" iyz="-6.9334E-12" izz="6.9397E-07" />
    </inertial>
    </link>
  <joint name="R_pinky_proximal_joint" type="revolute">
    <origin xyz="0.00028533 -0.13571 0.025488" rpy="3.0369 0 0" />
    <parent link="R_hand_base_link" />
    <child link="R_pinky_proximal" />
    <axis xyz="0 0 1" />
    <limit lower="0" upper="1.7" effort="1" velocity="0.5" />
  </joint>
  <link name="R_pinky_intermediate">
    <inertial>
      <origin xyz="0.0024748 0.016203 -0.0050031" rpy="0 0 0" />
      <mass value="0.0035996" />
      <inertia ixx="4.3913E-07" ixy="4.1418E-08" ixz="3.7168E-11" iyy="7.0247E-08" iyz="5.8613E-11" izz="4.4867E-07" />
    </inertial>
    </link>
  <joint name="R_pinky_intermediate_joint" type="revolute">
    <origin xyz="-0.0024229 0.032041 -0.001" rpy="0 0 0" />
    <parent link="R_pinky_proximal" />
    <child link="R_pinky_intermediate" />
    <axis xyz="0 0 1" />
    <limit lower="0" upper="1.7" effort="1" velocity="0.5" />
    <mimic joint="R_pinky_proximal_joint" multiplier="1" offset="0" />
  </joint>
<link name="pelvis_sphere1"><inertial><origin xyz="0 0 0" rpy="0 0 0" /><mass value="0.01" /><inertia ixx="0.001" ixy="0" ixz="0" iyy="0.001" iyz="0" izz="0.001" /></inertial><visual><origin rpy="0 0 0" xyz="0 0 0" /><geometry><sphere radius="0.06357467174530029" /></geometry><material name="color_pelvis_sphere1_0"><color rgba="0.9 0.2 0.2 1.0" /></material></visual><collision><origin rpy="0 0 0" xyz="0 0 0" /><geometry><sphere radius="0.06357467174530029" /></geometry><drake:proximity_properties><drake:rigid_hydroelastic /><drake:mesh_resolution_hint value="1.5" /><drake:hunt_crossley_dissipation value="1.25" /></drake:proximity_properties></collision></link><joint name="pelvis_to_pelvis_sphere1" type="fixed"><parent link="pelvis" /><child link="pelvis_sphere1" /><origin xyz="0.0003403265727683902 0.0009708564612083137 -0.038669947534799576" rpy="0 0 0" /></joint><link name="pelvis_sphere2"><inertial><origin xyz="0 0 0" rpy="0 0 0" /><mass value="0.01" /><inertia ixx="0.001" ixy="0" ixz="0" iyy="0.001" iyz="0" izz="0.001" /></inertial><visual><origin rpy="0 0 0" xyz="0 0 0" /><geometry><sphere radius="0.05728628858923912" /></geometry><material name="color_pelvis_sphere2_0"><color rgba="0.9 0.2 0.2 1.0" /></material></visual><collision><origin rpy="0 0 0" xyz="0 0 0" /><geometry><sphere radius="0.05728628858923912" /></geometry><drake:proximity_properties><drake:rigid_hydroelastic /><drake:mesh_resolution_hint value="1.5" /><drake:hunt_crossley_dissipation value="1.25" /></drake:proximity_properties></collision></link><joint name="pelvis_to_pelvis_sphere2" type="fixed"><parent link="pelvis" /><child link="pelvis_sphere2" /><origin xyz="-0.0011067589512094855 -0.09178908914327621 -0.04199345409870148" rpy="0 0 0" /></joint><link name="pelvis_sphere3"><inertial><origin xyz="0 0 0" rpy="0 0 0" /><mass value="0.01" /><inertia ixx="0.001" ixy="0" ixz="0" iyy="0.001" iyz="0" izz="0.001" /></inertial><visual><origin rpy="0 0 0" xyz="0 0 0" /><geometry><sphere radius="0.05668027326464653" /></geometry><material name="color_pelvis_sphere3_0"><color rgba="0.9 0.2 0.2 1.0" /></material></visual><collision><origin rpy="0 0 0" xyz="0 0 0" /><geometry><sphere radius="0.05668027326464653" /></geometry><drake:proximity_properties><drake:rigid_hydroelastic /><drake:mesh_resolution_hint value="1.5" /><drake:hunt_crossley_dissipation value="1.25" /></drake:proximity_properties></collision></link><joint name="pelvis_to_pelvis_sphere3" type="fixed"><parent link="pelvis" /><child link="pelvis_sphere3" /><origin xyz="-0.0006564579671248794 0.09162865579128265 -0.04301179572939873" rpy="0 0 0" /></joint><link name="torso_link_sphere1"><inertial><origin xyz="0 0 0" rpy="0 0 0" /><mass value="0.01" /><inertia ixx="0.001" ixy="0" ixz="0" iyy="0.001" iyz="0" izz="0.001" /></inertial><visual><origin rpy="0 0 0" xyz="0 0 0" /><geometry><sphere radius="0.10618707537651062" /></geometry><material name="color_torso_link_sphere1_0"><color rgba="0.9 0.2 0.2 1.0" /></material></visual><collision><origin rpy="0 0 0" xyz="0 0 0" /><geometry><sphere radius="0.10618707537651062" /></geometry><drake:proximity_properties><drake:rigid_hydroelastic /><drake:mesh_resolution_hint value="1.5" /><drake:hunt_crossley_dissipation value="1.25" /></drake:proximity_properties></collision></link><joint name="torso_link_to_torso_link_sphere1" type="fixed"><parent link="torso_link" /><child link="torso_link_sphere1" /><origin xyz="0.003478483995422721 -0.0007865214138291776 0.09114999324083328" rpy="0 0 0" /></joint><link name="torso_link_sphere2"><inertial><origin xyz="0 0 0" rpy="0 0 0" /><mass value="0.01" /><inertia ixx="0.001" ixy="0" ixz="0" iyy="0.001" iyz="0" izz="0.001" /></inertial><visual><origin rpy="0 0 0" xyz="0 0 0" /><geometry><sphere radius="0.08893471956253052" /></geometry><material name="color_torso_link_sphere2_0"><color rgba="0.9 0.2 0.2 1.0" /></material></visual><collision><origin rpy="0 0 0" xyz="0 0 0" /><geometry><sphere radius="0.08893471956253052" /></geometry><drake:proximity_properties><drake:rigid_hydroelastic /><drake:mesh_resolution_hint value="1.5" /><drake:hunt_crossley_dissipation value="1.25" /></drake:proximity_properties></collision></link><joint name="torso_link_to_torso_link_sphere2" type="fixed"><parent link="torso_link" /><child link="torso_link_sphere2" /><origin xyz="0.04515593871474266 -4.1305967897642404e-05 0.6715702414512634" rpy="0 0 0" /></joint><link name="torso_link_sphere3"><inertial><origin xyz="0 0 0" rpy="0 0 0" /><mass value="0.01" /><inertia ixx="0.001" ixy="0" ixz="0" iyy="0.001" iyz="0" izz="0.001" /></inertial><visual><origin rpy="0 0 0" xyz="0 0 0" /><geometry><sphere radius="0.11969899386167526" /></geometry><material name="color_torso_link_sphere3_0"><color rgba="0.9 0.2 0.2 1.0" /></material></visual><collision><origin rpy="0 0 0" xyz="0 0 0" /><geometry><sphere radius="0.11969899386167526" /></geometry><drake:proximity_properties><drake:rigid_hydroelastic /><drake:mesh_resolution_hint value="1.5" /><drake:hunt_crossley_dissipation value="1.25" /></drake:proximity_properties></collision></link><joint name="torso_link_to_torso_link_sphere3" type="fixed"><parent link="torso_link" /><child link="torso_link_sphere3" /><origin xyz="0.0101136090233922 -0.00015289020666386932 0.30636510252952576" rpy="0 0 0" /></joint><link name="torso_link_sphere4"><inertial><origin xyz="0 0 0" rpy="0 0 0" /><mass value="0.01" /><inertia ixx="0.001" ixy="0" ixz="0" iyy="0.001" iyz="0" izz="0.001" /></inertial><visual><origin rpy="0 0 0" xyz="0 0 0" /><geometry><sphere radius="0.11274947226047516" /></geometry><material name="color_torso_link_sphere4_0"><color rgba="0.9 0.2 0.2 1.0" /></material></visual><collision><origin rpy="0 0 0" xyz="0 0 0" /><geometry><sphere radius="0.11274947226047516" /></geometry><drake:proximity_properties><drake:rigid_hydroelastic /><drake:mesh_resolution_hint value="1.5" /><drake:hunt_crossley_dissipation value="1.25" /></drake:proximity_properties></collision></link><joint name="torso_link_to_torso_link_sphere4" type="fixed"><parent link="torso_link" /><child link="torso_link_sphere4" /><origin xyz="0.020222892984747887 0.00037389458157122135 0.5121726393699646" rpy="0 0 0" /></joint><link name="left_shoulder_pitch_link_sphere1"><inertial><origin xyz="0 0 0" rpy="0 0 0" /><mass value="0.01" /><inertia ixx="0.001" ixy="0" ixz="0" iyy="0.001" iyz="0" izz="0.001" /></inertial><visual><origin rpy="0 0 0" xyz="0 0 0" /><geometry><sphere radius="0.05021890252828598" /></geometry><material name="color_left_shoulder_pitch_link_sphere1_0"><color rgba="1.0 1.0 0.2 1.0" /></material></visual><collision><origin rpy="0 0 0" xyz="0 0 0" /><geometry><sphere radius="0.05021890252828598" /></geometry><drake:proximity_properties><drake:rigid_hydroelastic /><drake:mesh_resolution_hint value="1.5" /><drake:hunt_crossley_dissipation value="1.25" /></drake:proximity_properties></collision></link><joint name="left_shoulder_pitch_link_to_left_shoulder_pitch_link_sphere1" type="fixed"><parent link="left_shoulder_pitch_link" /><child link="left_shoulder_pitch_link_sphere1" /><origin xyz="-0.003680610563606024 0.05464700236916542 -0.005241498351097107" rpy="0 0 0" /></joint><link name="left_shoulder_roll_link_sphere1"><inertial><origin xyz="0 0 0" rpy="0 0 0" /><mass value="0.01" /><inertia ixx="0.001" ixy="0" ixz="0" iyy="0.001" iyz="0" izz="0.001" /></inertial><visual><origin rpy="0 0 0" xyz="0 0 0" /><geometry><sphere radius="0.0561298243701458" /></geometry><material name="color_left_shoulder_roll_link_sphere1_0"><color rgba="1.0 0.84 0.0 1.0" /></material></visual><collision><origin rpy="0 0 0" xyz="0 0 0" /><geometry><sphere radius="0.0561298243701458" /></geometry><drake:proximity_properties><drake:rigid_hydroelastic /><drake:mesh_resolution_hint value="1.5" /><drake:hunt_crossley_dissipation value="1.25" /></drake:proximity_properties></collision></link><joint name="left_shoulder_roll_link_to_left_shoulder_roll_link_sphere1" type="fixed"><parent link="left_shoulder_roll_link" /><child link="left_shoulder_roll_link_sphere1" /><origin xyz="-0.02705514244735241 -0.0003540052566677332 -0.07903210818767548" rpy="0 0 0" /></joint><link name="left_shoulder_yaw_link_sphere1"><inertial><origin xyz="0 0 0" rpy="0 0 0" /><mass value="0.01" /><inertia ixx="0.001" ixy="0" ixz="0" iyy="0.001" iyz="0" izz="0.001" /></inertial><visual><origin rpy="0 0 0" xyz="0 0 0" /><geometry><sphere radius="0.04590257629752159" /></geometry><material name="color_left_shoulder_yaw_link_sphere1_0"><color rgba="0.8 0.52 0.25 1.0" /></material></visual><collision><origin rpy="0 0 0" xyz="0 0 0" /><geometry><sphere radius="0.04590257629752159" /></geometry><drake:proximity_properties><drake:rigid_hydroelastic /><drake:mesh_resolution_hint value="1.5" /><drake:hunt_crossley_dissipation value="1.25" /></drake:proximity_properties></collision></link><joint name="left_shoulder_yaw_link_to_left_shoulder_yaw_link_sphere1" type="fixed"><parent link="left_shoulder_yaw_link" /><child link="left_shoulder_yaw_link_sphere1" /><origin xyz="0.0011504257563501596 -0.0008248673984780908 -0.0346042662858963" rpy="0 0 0" /></joint><link name="left_shoulder_yaw_link_sphere2"><inertial><origin xyz="0 0 0" rpy="0 0 0" /><mass value="0.01" /><inertia ixx="0.001" ixy="0" ixz="0" iyy="0.001" iyz="0" izz="0.001" /></inertial><visual><origin rpy="0 0 0" xyz="0 0 0" /><geometry><sphere radius="0.04926080256700516" /></geometry><material name="color_left_shoulder_yaw_link_sphere2_0"><color rgba="0.8 0.52 0.25 1.0" /></material></visual><collision><origin rpy="0 0 0" xyz="0 0 0" /><geometry><sphere radius="0.04926080256700516" /></geometry><drake:proximity_properties><drake:rigid_hydroelastic /><drake:mesh_resolution_hint value="1.5" /><drake:hunt_crossley_dissipation value="1.25" /></drake:proximity_properties></collision></link><joint name="left_shoulder_yaw_link_to_left_shoulder_yaw_link_sphere2" type="fixed"><parent link="left_shoulder_yaw_link" /><child link="left_shoulder_yaw_link_sphere2" /><origin xyz="0.006146916653960943 -0.0043021757155656815 -0.18221591413021088" rpy="0 0 0" /></joint><link name="left_shoulder_yaw_link_sphere3"><inertial><origin xyz="0 0 0" rpy="0 0 0" /><mass value="0.01" /><inertia ixx="0.001" ixy="0" ixz="0" iyy="0.001" iyz="0" izz="0.001" /></inertial><visual><origin rpy="0 0 0" xyz="0 0 0" /><geometry><sphere radius="0.048234403133392334" /></geometry><material name="color_left_shoulder_yaw_link_sphere3_0"><color rgba="0.8 0.52 0.25 1.0" /></material></visual><collision><origin rpy="0 0 0" xyz="0 0 0" /><geometry><sphere radius="0.048234403133392334" /></geometry><drake:proximity_properties><drake:rigid_hydroelastic /><drake:mesh_resolution_hint value="1.5" /><drake:hunt_crossley_dissipation value="1.25" /></drake:proximity_properties></collision></link><joint name="left_shoulder_yaw_link_to_left_shoulder_yaw_link_sphere3" type="fixed"><parent link="left_shoulder_yaw_link" /><child link="left_shoulder_yaw_link_sphere3" /><origin xyz="0.003462175140157342 -0.0024497846607118845 -0.10537935793399811" rpy="0 0 0" /></joint><link name="left_elbow_link_sphere1"><inertial><origin xyz="0 0 0" rpy="0 0 0" /><mass value="0.01" /><inertia ixx="0.001" ixy="0" ixz="0" iyy="0.001" iyz="0" izz="0.001" /></inertial><visual><origin rpy="0 0 0" xyz="0 0 0" /><geometry><sphere radius="0.037453651428222656" /></geometry><material name="color_left_elbow_link_sphere1_0"><color rgba="0.95 0.95 0.5 1.0" /></material></visual><collision><origin rpy="0 0 0" xyz="0 0 0" /><geometry><sphere radius="0.037453651428222656" /></geometry><drake:proximity_properties><drake:rigid_hydroelastic /><drake:mesh_resolution_hint value="1.5" /><drake:hunt_crossley_dissipation value="1.25" /></drake:proximity_properties></collision></link><joint name="left_elbow_link_to_left_elbow_link_sphere1" type="fixed"><parent link="left_elbow_link" /><child link="left_elbow_link_sphere1" /><origin xyz="0.008503979071974754 -0.01428496278822422 -0.0016332389786839485" rpy="0 0 0" /></joint><link name="left_elbow_link_sphere2"><inertial><origin xyz="0 0 0" rpy="0 0 0" /><mass value="0.01" /><inertia ixx="0.001" ixy="0" ixz="0" iyy="0.001" iyz="0" izz="0.001" /></inertial><visual><origin rpy="0 0 0" xyz="0 0 0" /><geometry><sphere radius="0.04101834446191788" /></geometry><material name="color_left_elbow_link_sphere2_0"><color rgba="0.95 0.95 0.5 1.0" /></material></visual><collision><origin rpy="0 0 0" xyz="0 0 0" /><geometry><sphere radius="0.04101834446191788" /></geometry><drake:proximity_properties><drake:rigid_hydroelastic /><drake:mesh_resolution_hint value="1.5" /><drake:hunt_crossley_dissipation value="1.25" /></drake:proximity_properties></collision></link><joint name="left_elbow_link_to_left_elbow_link_sphere2" type="fixed"><parent link="left_elbow_link" /><child link="left_elbow_link_sphere2" /><origin xyz="0.08459305018186569 -0.0312232356518507 -0.008993495255708694" rpy="0 0 0" /></joint><link name="left_wrist_roll_link_sphere1"><inertial><origin xyz="0 0 0" rpy="0 0 0" /><mass value="0.01" /><inertia ixx="0.001" ixy="0" ixz="0" iyy="0.001" iyz="0" izz="0.001" /></inertial><visual><origin rpy="0 0 0" xyz="0 0 0" /><geometry><sphere radius="0.04320788383483887" /></geometry><material name="color_left_wrist_roll_link_sphere1_0"><color rgba="0.7 0.5 0.1 1.0" /></material></visual><collision><origin rpy="0 0 0" xyz="0 0 0" /><geometry><sphere radius="0.04320788383483887" /></geometry><drake:proximity_properties><drake:rigid_hydroelastic /><drake:mesh_resolution_hint value="1.5" /><drake:hunt_crossley_dissipation value="1.25" /></drake:proximity_properties></collision></link><joint name="left_wrist_roll_link_to_left_wrist_roll_link_sphere1" type="fixed"><parent link="left_wrist_roll_link" /><child link="left_wrist_roll_link_sphere1" /><origin xyz="0.04196289926767349 -0.0007462173816747963 -0.00012633352889679372" rpy="0 0 0" /></joint><link name="left_wrist_pitch_link_sphere1"><inertial><origin xyz="0 0 0" rpy="0 0 0" /><mass value="0.01" /><inertia ixx="0.001" ixy="0" ixz="0" iyy="0.001" iyz="0" izz="0.001" /></inertial><visual><origin rpy="0 0 0" xyz="0 0 0" /><geometry><sphere radius="0.03572520613670349" /></geometry><material name="color_left_wrist_pitch_link_sphere1_0"><color rgba="1.0 0.9 0.4 1.0" /></material></visual><collision><origin rpy="0 0 0" xyz="0 0 0" /><geometry><sphere radius="0.03572520613670349" /></geometry><drake:proximity_properties><drake:rigid_hydroelastic /><drake:mesh_resolution_hint value="1.5" /><drake:hunt_crossley_dissipation value="1.25" /></drake:proximity_properties></collision></link><joint name="left_wrist_pitch_link_to_left_wrist_pitch_link_sphere1" type="fixed"><parent link="left_wrist_pitch_link" /><child link="left_wrist_pitch_link_sphere1" /><origin xyz="0.019083457067608833 -4.399214594741352e-05 0.0007478207116946578" rpy="0 0 0" /></joint><link name="left_wrist_yaw_link_sphere1"><inertial><origin xyz="0 0 0" rpy="0 0 0" /><mass value="0.01" /><inertia ixx="0.001" ixy="0" ixz="0" iyy="0.001" iyz="0" izz="0.001" /></inertial><visual><origin rpy="0 0 0" xyz="0 0 0" /><geometry><sphere radius="0.0401243194937706" /></geometry><material name="color_left_wrist_yaw_link_sphere1_0"><color rgba="0.6 0.4 0.1 1.0" /></material></visual><collision><origin rpy="0 0 0" xyz="0 0 0" /><geometry><sphere radius="0.0401243194937706" /></geometry><drake:proximity_properties><drake:rigid_hydroelastic /><drake:mesh_resolution_hint value="1.5" /><drake:hunt_crossley_dissipation value="1.25" /></drake:proximity_properties></collision></link><joint name="left_wrist_yaw_link_to_left_wrist_yaw_link_sphere1" type="fixed"><parent link="left_wrist_yaw_link" /><child link="left_wrist_yaw_link_sphere1" /><origin xyz="0.025164952501654625 -0.0002986877807416022 -8.146732579916716e-05" rpy="0 0 0" /></joint><link name="right_shoulder_pitch_link_sphere1"><inertial><origin xyz="0 0 0" rpy="0 0 0" /><mass value="0.01" /><inertia ixx="0.001" ixy="0" ixz="0" iyy="0.001" iyz="0" izz="0.001" /></inertial><visual><origin rpy="0 0 0" xyz="0 0 0" /><geometry><sphere radius="0.05052950978279114" /></geometry><material name="color_right_shoulder_pitch_link_sphere1_0"><color rgba="0.8 0.2 1.0 1.0" /></material></visual><collision><origin rpy="0 0 0" xyz="0 0 0" /><geometry><sphere radius="0.05052950978279114" /></geometry><drake:proximity_properties><drake:rigid_hydroelastic /><drake:mesh_resolution_hint value="1.5" /><drake:hunt_crossley_dissipation value="1.25" /></drake:proximity_properties></collision></link><joint name="right_shoulder_pitch_link_to_right_shoulder_pitch_link_sphere1" type="fixed"><parent link="right_shoulder_pitch_link" /><child link="right_shoulder_pitch_link_sphere1" /><origin xyz="-0.00400080531835556 -0.054801035672426224 -0.005326153244823217" rpy="0 0 0" /></joint><link name="right_shoulder_roll_link_sphere1"><inertial><origin xyz="0 0 0" rpy="0 0 0" /><mass value="0.01" /><inertia ixx="0.001" ixy="0" ixz="0" iyy="0.001" iyz="0" izz="0.001" /></inertial><visual><origin rpy="0 0 0" xyz="0 0 0" /><geometry><sphere radius="0.05629420652985573" /></geometry><material name="color_right_shoulder_roll_link_sphere1_0"><color rgba="0.6 0.3 0.8 1.0" /></material></visual><collision><origin rpy="0 0 0" xyz="0 0 0" /><geometry><sphere radius="0.05629420652985573" /></geometry><drake:proximity_properties><drake:rigid_hydroelastic /><drake:mesh_resolution_hint value="1.5" /><drake:hunt_crossley_dissipation value="1.25" /></drake:proximity_properties></collision></link><joint name="right_shoulder_roll_link_to_right_shoulder_roll_link_sphere1" type="fixed"><parent link="right_shoulder_roll_link" /><child link="right_shoulder_roll_link_sphere1" /><origin xyz="-0.027096537873148918 -0.0006400610436685383 -0.07835514843463898" rpy="0 0 0" /></joint><link name="right_shoulder_yaw_link_sphere1"><inertial><origin xyz="0 0 0" rpy="0 0 0" /><mass value="0.01" /><inertia ixx="0.001" ixy="0" ixz="0" iyy="0.001" iyz="0" izz="0.001" /></inertial><visual><origin rpy="0 0 0" xyz="0 0 0" /><geometry><sphere radius="0.04954177513718605" /></geometry><material name="color_right_shoulder_yaw_link_sphere1_0"><color rgba="0.5 0.1 0.5 1.0" /></material></visual><collision><origin rpy="0 0 0" xyz="0 0 0" /><geometry><sphere radius="0.04954177513718605" /></geometry><drake:proximity_properties><drake:rigid_hydroelastic /><drake:mesh_resolution_hint value="1.5" /><drake:hunt_crossley_dissipation value="1.25" /></drake:proximity_properties></collision></link><joint name="right_shoulder_yaw_link_to_right_shoulder_yaw_link_sphere1" type="fixed"><parent link="right_shoulder_yaw_link" /><child link="right_shoulder_yaw_link_sphere1" /><origin xyz="0.006087132729589939 0.004507239907979965 -0.18166829645633698" rpy="0 0 0" /></joint><link name="right_shoulder_yaw_link_sphere2"><inertial><origin xyz="0 0 0" rpy="0 0 0" /><mass value="0.01" /><inertia ixx="0.001" ixy="0" ixz="0" iyy="0.001" iyz="0" izz="0.001" /></inertial><visual><origin rpy="0 0 0" xyz="0 0 0" /><geometry><sphere radius="0.048371464014053345" /></geometry><material name="color_right_shoulder_yaw_link_sphere2_0"><color rgba="0.5 0.1 0.5 1.0" /></material></visual><collision><origin rpy="0 0 0" xyz="0 0 0" /><geometry><sphere radius="0.048371464014053345" /></geometry><drake:proximity_properties><drake:rigid_hydroelastic /><drake:mesh_resolution_hint value="1.5" /><drake:hunt_crossley_dissipation value="1.25" /></drake:proximity_properties></collision></link><joint name="right_shoulder_yaw_link_to_right_shoulder_yaw_link_sphere2" type="fixed"><parent link="right_shoulder_yaw_link" /><child link="right_shoulder_yaw_link_sphere2" /><origin xyz="0.0031784051097929478 0.002170092659071088 -0.10315534472465515" rpy="0 0 0" /></joint><link name="right_shoulder_yaw_link_sphere3"><inertial><origin xyz="0 0 0" rpy="0 0 0" /><mass value="0.01" /><inertia ixx="0.001" ixy="0" ixz="0" iyy="0.001" iyz="0" izz="0.001" /></inertial><visual><origin rpy="0 0 0" xyz="0 0 0" /><geometry><sphere radius="0.04583407938480377" /></geometry><material name="color_right_shoulder_yaw_link_sphere3_0"><color rgba="0.5 0.1 0.5 1.0" /></material></visual><collision><origin rpy="0 0 0" xyz="0 0 0" /><geometry><sphere radius="0.04583407938480377" /></geometry><drake:proximity_properties><drake:rigid_hydroelastic /><drake:mesh_resolution_hint value="1.5" /><drake:hunt_crossley_dissipation value="1.25" /></drake:proximity_properties></collision></link><joint name="right_shoulder_yaw_link_to_right_shoulder_yaw_link_sphere3" type="fixed"><parent link="right_shoulder_yaw_link" /><child link="right_shoulder_yaw_link_sphere3" /><origin xyz="0.0009786337614059448 0.0006730608292855322 -0.03414745628833771" rpy="0 0 0" /></joint><link name="right_elbow_link_sphere1"><inertial><origin xyz="0 0 0" rpy="0 0 0" /><mass value="0.01" /><inertia ixx="0.001" ixy="0" ixz="0" iyy="0.001" iyz="0" izz="0.001" /></inertial><visual><origin rpy="0 0 0" xyz="0 0 0" /><geometry><sphere radius="0.0409969687461853" /></geometry><material name="color_right_elbow_link_sphere1_0"><color rgba="0.9 0.5 1.0 1.0" /></material></visual><collision><origin rpy="0 0 0" xyz="0 0 0" /><geometry><sphere radius="0.0409969687461853" /></geometry><drake:proximity_properties><drake:rigid_hydroelastic /><drake:mesh_resolution_hint value="1.5" /><drake:hunt_crossley_dissipation value="1.25" /></drake:proximity_properties></collision></link><joint name="right_elbow_link_to_right_elbow_link_sphere1" type="fixed"><parent link="right_elbow_link" /><child link="right_elbow_link_sphere1" /><origin xyz="0.08541678637266159 0.03081882745027542 -0.0092054083943367" rpy="0 0 0" /></joint><link name="right_elbow_link_sphere2"><inertial><origin xyz="0 0 0" rpy="0 0 0" /><mass value="0.01" /><inertia ixx="0.001" ixy="0" ixz="0" iyy="0.001" iyz="0" izz="0.001" /></inertial><visual><origin rpy="0 0 0" xyz="0 0 0" /><geometry><sphere radius="0.03794165328145027" /></geometry><material name="color_right_elbow_link_sphere2_0"><color rgba="0.9 0.5 1.0 1.0" /></material></visual><collision><origin rpy="0 0 0" xyz="0 0 0" /><geometry><sphere radius="0.03794165328145027" /></geometry><drake:proximity_properties><drake:rigid_hydroelastic /><drake:mesh_resolution_hint value="1.5" /><drake:hunt_crossley_dissipation value="1.25" /></drake:proximity_properties></collision></link><joint name="right_elbow_link_to_right_elbow_link_sphere2" type="fixed"><parent link="right_elbow_link" /><child link="right_elbow_link_sphere2" /><origin xyz="0.00833866186439991 0.013942179270088673 -0.001740008476190269" rpy="0 0 0" /></joint><link name="right_wrist_roll_link_sphere1"><inertial><origin xyz="0 0 0" rpy="0 0 0" /><mass value="0.01" /><inertia ixx="0.001" ixy="0" ixz="0" iyy="0.001" iyz="0" izz="0.001" /></inertial><visual><origin rpy="0 0 0" xyz="0 0 0" /><geometry><sphere radius="0.04306594654917717" /></geometry><material name="color_right_wrist_roll_link_sphere1_0"><color rgba="0.7 0.3 0.7 1.0" /></material></visual><collision><origin rpy="0 0 0" xyz="0 0 0" /><geometry><sphere radius="0.04306594654917717" /></geometry><drake:proximity_properties><drake:rigid_hydroelastic /><drake:mesh_resolution_hint value="1.5" /><drake:hunt_crossley_dissipation value="1.25" /></drake:proximity_properties></collision></link><joint name="right_wrist_roll_link_to_right_wrist_roll_link_sphere1" type="fixed"><parent link="right_wrist_roll_link" /><child link="right_wrist_roll_link_sphere1" /><origin xyz="0.041614972054958344 0.0007400974282063544 -5.998512642690912e-05" rpy="0 0 0" /></joint><link name="right_wrist_pitch_link_sphere1"><inertial><origin xyz="0 0 0" rpy="0 0 0" /><mass value="0.01" /><inertia ixx="0.001" ixy="0" ixz="0" iyy="0.001" iyz="0" izz="0.001" /></inertial><visual><origin rpy="0 0 0" xyz="0 0 0" /><geometry><sphere radius="0.035736940801143646" /></geometry><material name="color_right_wrist_pitch_link_sphere1_0"><color rgba="0.6 0.2 0.6 1.0" /></material></visual><collision><origin rpy="0 0 0" xyz="0 0 0" /><geometry><sphere radius="0.035736940801143646" /></geometry><drake:proximity_properties><drake:rigid_hydroelastic /><drake:mesh_resolution_hint value="1.5" /><drake:hunt_crossley_dissipation value="1.25" /></drake:proximity_properties></collision></link><joint name="right_wrist_pitch_link_to_right_wrist_pitch_link_sphere1" type="fixed"><parent link="right_wrist_pitch_link" /><child link="right_wrist_pitch_link_sphere1" /><origin xyz="0.01896509900689125 -1.5579093087580986e-05 0.0005533848307095468" rpy="0 0 0" /></joint><link name="right_wrist_yaw_link_sphere1"><inertial><origin xyz="0 0 0" rpy="0 0 0" /><mass value="0.01" /><inertia ixx="0.001" ixy="0" ixz="0" iyy="0.001" iyz="0" izz="0.001" /></inertial><visual><origin rpy="0 0 0" xyz="0 0 0" /><geometry><sphere radius="0.0401243194937706" /></geometry><material name="color_right_wrist_yaw_link_sphere1_0"><color rgba="0.4 0.1 0.4 1.0" /></material></visual><collision><origin rpy="0 0 0" xyz="0 0 0" /><geometry><sphere radius="0.0401243194937706" /></geometry><drake:proximity_properties><drake:rigid_hydroelastic /><drake:mesh_resolution_hint value="1.5" /><drake:hunt_crossley_dissipation value="1.25" /></drake:proximity_properties></collision></link><joint name="right_wrist_yaw_link_to_right_wrist_yaw_link_sphere1" type="fixed"><parent link="right_wrist_yaw_link" /><child link="right_wrist_yaw_link_sphere1" /><origin xyz="0.025164952501654625 -0.0002986877807416022 -8.146732579916716e-05" rpy="0 0 0" /></joint><link name="L_hand_base_link_sphere1"><inertial><origin xyz="0 0 0" rpy="0 0 0" /><mass value="0.01" /><inertia ixx="0.001" ixy="0" ixz="0" iyy="0.001" iyz="0" izz="0.001" /></inertial><visual><origin rpy="0 0 0" xyz="0 0 0" /><geometry><sphere radius="0.034013260155916214" /></geometry><material name="color_L_hand_base_link_sphere1_0"><color rgba="0.2 0.9 0.9 1.0" /></material></visual><collision><origin rpy="0 0 0" xyz="0 0 0" /><geometry><sphere radius="0.034013260155916214" /></geometry><drake:proximity_properties><drake:rigid_hydroelastic /><drake:mesh_resolution_hint value="1.5" /><drake:hunt_crossley_dissipation value="1.25" /></drake:proximity_properties></collision></link><joint name="L_hand_base_link_to_L_hand_base_link_sphere1" type="fixed"><parent link="L_hand_base_link" /><child link="L_hand_base_link_sphere1" /><origin xyz="-0.0006466718623414636 -0.03156209737062454 -0.0005412321770563722" rpy="0 0 0" /></joint><link name="L_hand_base_link_sphere2"><inertial><origin xyz="0 0 0" rpy="0 0 0" /><mass value="0.01" /><inertia ixx="0.001" ixy="0" ixz="0" iyy="0.001" iyz="0" izz="0.001" /></inertial><visual><origin rpy="0 0 0" xyz="0 0 0" /><geometry><sphere radius="0.03349905088543892" /></geometry><material name="color_L_hand_base_link_sphere2_0"><color rgba="0.2 0.9 0.9 1.0" /></material></visual><collision><origin rpy="0 0 0" xyz="0 0 0" /><geometry><sphere radius="0.03349905088543892" /></geometry><drake:proximity_properties><drake:rigid_hydroelastic /><drake:mesh_resolution_hint value="1.5" /><drake:hunt_crossley_dissipation value="1.25" /></drake:proximity_properties></collision></link><joint name="L_hand_base_link_to_L_hand_base_link_sphere2" type="fixed"><parent link="L_hand_base_link" /><child link="L_hand_base_link_sphere2" /><origin xyz="0.0008343164226971567 -0.10056782513856888 -0.002129173604771495" rpy="0 0 0" /></joint><link name="R_hand_base_link_sphere1"><inertial><origin xyz="0 0 0" rpy="0 0 0" /><mass value="0.01" /><inertia ixx="0.001" ixy="0" ixz="0" iyy="0.001" iyz="0" izz="0.001" /></inertial><visual><origin rpy="0 0 0" xyz="0 0 0" /><geometry><sphere radius="0.03315259888768196" /></geometry><material name="color_R_hand_base_link_sphere1_0"><color rgba="0.9 0.6 0.2 1.0" /></material></visual><collision><origin rpy="0 0 0" xyz="0 0 0" /><geometry><sphere radius="0.03315259888768196" /></geometry><drake:proximity_properties><drake:rigid_hydroelastic /><drake:mesh_resolution_hint value="1.5" /><drake:hunt_crossley_dissipation value="1.25" /></drake:proximity_properties></collision></link><joint name="R_hand_base_link_to_R_hand_base_link_sphere1" type="fixed"><parent link="R_hand_base_link" /><child link="R_hand_base_link_sphere1" /><origin xyz="0.0004720503347925842 -0.10079444944858551 0.002042673295363784" rpy="0 0 0" /></joint><link name="R_hand_base_link_sphere2"><inertial><origin xyz="0 0 0" rpy="0 0 0" /><mass value="0.01" /><inertia ixx="0.001" ixy="0" ixz="0" iyy="0.001" iyz="0" izz="0.001" /></inertial><visual><origin rpy="0 0 0" xyz="0 0 0" /><geometry><sphere radius="0.034181445837020874" /></geometry><material name="color_R_hand_base_link_sphere2_0"><color rgba="0.9 0.6 0.2 1.0" /></material></visual><collision><origin rpy="0 0 0" xyz="0 0 0" /><geometry><sphere radius="0.034181445837020874" /></geometry><drake:proximity_properties><drake:rigid_hydroelastic /><drake:mesh_resolution_hint value="1.5" /><drake:hunt_crossley_dissipation value="1.25" /></drake:proximity_properties></collision></link><joint name="R_hand_base_link_to_R_hand_base_link_sphere2" type="fixed"><parent link="R_hand_base_link" /><child link="R_hand_base_link_sphere2" /><origin xyz="-0.0007574863266199827 -0.031890444457530975 0.0008353672455996275" rpy="0 0 0" /></joint></robot>